<?xml version="1.0" ?>
<sdf version="1.5">
	<model name="google_grasp">
		<link name="base_link">
			<pose>0.0 0.0 0.0 0.0 -0.0 0.0</pose>
			<inertial>
				<mass>1000.0</mass>
				<pose>0.0 0.0 0.0 0.0 -0.0 0.0</pose>
				<inertia>
					<ixx>100.0</ixx>
					<ixy>0.0</ixy>
					<ixz>1.0</ixz>
					<iyy>100.0</iyy>
					<iyz>1.0</iyz>
					<izz>100.0</izz>
				</inertia>
			</inertial>
			<collision name="VIS_Camera_Fixture_Coll_2">
				<pose>0.28347 -0.33897 1.455229 0.0 -0.0 0.0</pose>
				<geometry>
					<mesh>
						<uri>model://google_grasp/meshes/visual/VIS_Camera_Fixture_Coll_2.dae</uri>
						<scale>0.04 0.04 0.45</scale>
					</mesh>
				</geometry>
			</collision>
			<collision name="VIS_base_link_table_1">
				<pose>-0.02010 -0.29250 0.38800 0.0 -0.0 0.0</pose>
				<geometry>
					<mesh>
						<uri>model://google_grasp/meshes/visual/VIS_base_link_table_1.dae</uri>
						<scale>0.44 0.90 0.39</scale>
					</mesh>
				</geometry>
			</collision>
			<collision name="VIS_Bins_12_Coll">
				<pose>-0.02002 -0.87279 0.71200 1.57080 -0.0 0.0</pose>
				<geometry>
					<mesh>
						<uri>model://google_grasp/meshes/visual/VIS_Bins_12_Coll.dae</uri>
						<scale>0.01 0.011 0.01</scale>
					</mesh>
				</geometry>
			</collision>
			<visual name="VIS_Camera_9_4">
				<pose>0.32804 -0.43959 1.63634 -1.15192 5.08527e-15 -3.1416</pose>
				<geometry>
					<mesh>
						<uri>model://google_grasp/meshes/visual/VIS_Camera_9_4.dae</uri>
						<scale>0.01 0.01 0.01</scale>
					</mesh>
				</geometry>
			</visual>
			<visual name="VIS_Camera_Fixture_10_3">
				<pose>0.26528 -0.33789 1.11712 1.570796 -0.0 0.0</pose>
				<geometry>
					<mesh>
						<uri>model://google_grasp/meshes/visual/VIS_Camera_Fixture_10_3.dae</uri>
						<scale>0.007 0.009 0.007</scale>
					</mesh>
				</geometry>
			</visual>
			<visual name="VIS_Table_11_2">
				<pose>-0.02002 -0.87278 0.71271 1.57079 -0.0 0.0</pose>
				<geometry>
					<mesh>
						<uri>model://google_grasp/meshes/visual/VIS_Table_11_2.dae</uri>
						<scale>0.008 0.011 0.008</scale>
					</mesh>
				</geometry>
			</visual>
			<visual name="VIS_Bins_12">
				<pose>-0.02000 -0.87279 0.71200 1.570796 -0.0 0.0</pose>
				<geometry>
					<mesh>
						<uri>model://google_grasp/meshes/visual/VIS_Bins_12_Coll.dae</uri>
						<scale>0.008 0.011 0.008</scale>
					</mesh>
				</geometry>
			</visual>
			<visual name="VIS_base_link_13">
				<pose>0.0 0.0 0.5 0.0 -0.0 0.0</pose>
				<geometry>
					<mesh>
						<uri>model://google_grasp/meshes/visual/VIS_base_link_13.dae</uri>
						<scale>1.0 1.0 1.0</scale>
					</mesh>
				</geometry>
			</visual>

			<sensor type="camera" name="camera_eye">
        			<pose>0.32 -0.44 1.65 3.14 2.0 1.24</pose>
        			<update_rate>30.0</update_rate>
        			<always_on>1</always_on>
        			<visualize>true</visualize>
        			<topic>/grasping_camera/image</topic>
        			<camera name="camera_eye">
          				<horizontal_fov>0.9</horizontal_fov>
          				<image>
            					<width>320</width>
            					<height>240</height>
            					<format>R8G8B8</format>
          				</image>
          				<clip>
            					<near>0.01</near>
            					<far>100</far>
          				</clip>
					<!--
          				<noise>
            					<type>gaussian</type>-->
            					<!-- Noise is sampled independently per pixel on each frame.
                 				That pixel's noise value is added to each of its color
                 				channels, which at that point lie in the range [0,1]. -->
						<!--            <mean>0.0</mean>
            					<stddev>0.007</stddev>
          				</noise>
					-->
        			</camera>
       				<plugin name="camera_controller" filename="libgazebo_ros_camera.so">
      					<alwaysOn>true</alwaysOn>
          				<updateRate>30.0</updateRate>
          				<cameraName>camera_eye</cameraName>
          				<imageTopicName>image_raw</imageTopicName>
          				<cameraInfoTopicName>camera_info</cameraInfoTopicName>
          				<frameName>camera_link</frameName>
          				<hackBaseline>0.07</hackBaseline>
          				<distortionK1>0.0</distortionK1>
         				<distortionK2>0.0</distortionK2>
          				<distortionK3>0.0</distortionK3>
          				<distortionT1>0.0</distortionT1>
          				<distortionT2>0.0</distortionT2>
        			</plugin>
      			</sensor>
		</link>
<!-- manipulation arm_0-->
		<link name="arm_0_link_link_base_z_rot">
			<pose>0.0 -0.4 1.0 0.0 -0.0 1.62316</pose>
			<inertial>
				<mass>0.29364</mass>
				<pose>0.0 0.0 0.0 0.0 -0.0 -0.0</pose>
				<inertia>
					<ixx>0.01</ixx>
					<ixy>0.0</ixy>
					<ixz>0.0</ixz>
					<iyy>0.01</iyy>
					<iyz>0.0</iyz>
					<izz>0.01</izz>
				</inertia>
			</inertial>
		</link>
<!-- arm_1 -->
		<link name="hollie_000">
			<pose>0 -0.4 1.11 0.0 -0.0 1.62316</pose>
			<inertial>
				<mass>0.29364</mass>
				<pose>0.0 0.0 0.0 0.0 -0.0 0.0</pose>
				<inertia>
					<ixx>0.01</ixx>
					<ixy>0.0</ixy>
					<ixz>0.0</ixz>
					<iyy>0.01</iyy>
					<iyz>0.0</iyz>
					<izz>0.01</izz>
				</inertia>
			</inertial>
			<collision name="VIS_hollhollie_000_Coll">
				<pose>3.52010e-08 1.03013e-07 1.54972e-06 -2.10125e-07 1.15808e-08 1.15484e-07</pose>
				<geometry>
					<mesh>
						<uri>model://google_grasp/meshes/visual/VIS_hollhollie_000_Coll.dae</uri>
						<scale>1.0 1.0 1.0</scale>
					</mesh>
				</geometry>
			</collision>
			<visual name="VIS_hollhollie_000">
				<pose>3.527899039568183e-08 1.0450104781511982e-07 1.5497207641601562e-06 -2.1012502315898018e-07 1.1580821634993299e-08 1.1548399925231934e-07</pose>
				<geometry>
					<mesh>
						<uri>model://google_grasp/meshes/visual/VIS_hollhollie_000.dae</uri>
						<scale>1.0 1.0 1.0</scale>
					</mesh>
				</geometry>
			</visual>
		</link>
<!-- arm_2 -->
		<link name="hollie_001_base_x_rot">
			<pose>0 -0.4 1.11 1.5708 0.0 1.62316</pose>
			<inertial>
				<mass>1.68311</mass>
				<pose>0.0 0.0 0.0 0.0 0.0 0.0</pose>
				<inertia>
					<ixx>0.03</ixx>
					<ixy>0.0</ixy>
					<ixz>0.0</ixz>
					<iyy>0.03</iyy>
					<iyz>0.0</iyz>
					<izz>0.03</izz>
				</inertia>
			</inertial>
			<collision name="VIS_hollhollie_001_base_x_rot_Coll">
				<pose>1.237239644069632e-07 1.4319995216283132e-06 2.0726911853508057e-10 -7.549789415861596e-08 4.842877388000488e-08 5.42986633433884e-08</pose>
				<geometry>
					<mesh>
						<uri>model://google_grasp/meshes/visual/VIS_hollhollie_001_base_x_rot_Coll.dae</uri>
						<scale>1.0 1.0 1.0</scale>
					</mesh>
				</geometry>
			</collision>
			<visual name="VIS_hollhollie_001_base_x_rot">
				<pose>9.382646481981283e-08 1.4319995216283132e-06 1.6081827536318372e-10 -7.549789415861596e-08 4.842877388000488e-08 5.42986633433884e-08</pose>
				<geometry>
					<mesh>
						<uri>model://google_grasp/meshes/visual/VIS_hollhollie_001_base_x_rot.dae</uri>
						<scale>1.0 1.0 1.0</scale>
					</mesh>
				</geometry>
			</visual>
		</link>
<!-- arm_3-->
		<link name="hollie_002_upper_x_rot">
			<pose>2.226621420892171e-06 -0.3999998892682126 1.4599999934433918 1.5707963705062908 -8.742278039484667e-08 -1.5184365510940514</pose>
			<inertial>
				<mass>2.1</mass>
				<pose>0.0 0.0 0.0 0.0 0.0 0.0</pose>
				<inertia>
					<ixx>0.03</ixx>
					<ixy>0.0</ixy>
					<ixz>0.0</ixz>
					<iyy>0.03</iyy>
					<iyz>0.0</iyz>
					<izz>0.03</izz>
				</inertia>
			</inertial>
			<collision name="VIS_hollhollie_002_upper_x_rot_Coll">
				<pose>-2.3484392386308173e-07 1.0386088433733676e-06 6.178673572776461e-09 1.1914856656858319e-07 5.252659320831299e-07 -2.3818108374484837e-08</pose>
				<geometry>
					<mesh>
						<uri>model://google_grasp/meshes/visual/VIS_hollhollie_002_upper_x_rot_Coll.dae</uri>
						<scale>1.0 1.0 1.0</scale>
					</mesh>
				</geometry>
			</collision>
			<visual name="VIS_hollhollie_002_upper_x_rot">
				<pose>-2.348423038256442e-07 1.0386088433733676e-06 6.147750752916181e-09 1.1914856656858319e-07 5.252659320831299e-07 -2.3818108374484837e-08</pose>
				<geometry>
					<mesh>
						<uri>model://google_grasp/meshes/visual/VIS_hollhollie_002_upper_x_rot.dae</uri>
						<scale>1.0 1.0 1.0</scale>
					</mesh>
				</geometry>
			</visual>
		</link>
<!--arm_4-->
		<link name="hollie_003">
			<pose>2.226621420892171e-06 -0.3999998892682126 1.4599999934433916 -4.2188485748648916e-15 2.384185794926842e-07 1.6231561024957353</pose>
			<inertial>
				<mass>1.68311</mass>
				<pose>0.0 0.0 0.0 0.0 0.0 0.0</pose>
				<inertia>
					<ixx>0.1</ixx>
					<ixy>0.1</ixy>
					<ixz>0.1</ixz>
					<iyy>0.1</iyy>
					<iyz>0.1</iyz>
					<izz>0.1</izz>
				</inertia>
			</inertial>
			<collision name="VIS_hollhollie_003_Coll">
				<pose>2.7709091909855488e-08 -1.3419257527402806e-07 5.3661583621078535e-08 2.55391114478698e-07 1.2251870629143014e-08 -6.332995639013461e-08</pose>
				<geometry>
					<mesh>
						<uri>model://google_grasp/meshes/visual/VIS_hollhollie_003_Coll.dae</uri>
						<scale>1.0 1.0 1.0</scale>
					</mesh>
				</geometry>
			</collision>
			<visual name="VIS_hollhollie_003">
				<pose>4.941942677305633e-08 -2.9045969540675287e-07 5.3661583621078535e-08 2.5077753207369824e-07 4.84698337022138e-10 -6.332995639013461e-08</pose>
				<geometry>
					<mesh>
						<uri>model://google_grasp/meshes/visual/VIS_hollhollie_003.dae</uri>
						<scale>1.0 1.0 1.0</scale>
					</mesh>
				</geometry>
			</visual>
		</link>
<!--arm_5-->
		<link name="hollie_004_wrist_x_rot">
			<pose>-0.005237775420036871 -0.40026984862109644 1.7650000005948487 1.5707963705063268 -2.384185794926808e-07 -1.518436702089857</pose>
			<inertial>
				<mass>0.807</mass>
				<pose>0.0 0.0 0.0 0.0 0.0 0.0</pose>
				<inertia>
					<ixx>0.03</ixx>
					<ixy>0.0</ixy>
					<ixz>0.0</ixz>
					<iyy>0.03</iyy>
					<iyz>0.0</iyz>
					<izz>0.03</izz>
				</inertia>
			</inertial>
			<collision name="VIS_hollhollie_004_wrist_x_rot_Coll">
				<pose>-2.576303472778818e-07 6.274480597312504e-07 -5.579038031555683e-08 1.9072874692938058e-06 -2.2016463390173158e-06 3.1112062259808226e-08</pose>
				<geometry>
					<mesh>
						<uri>model://google_grasp/meshes/visual/VIS_hollhollie_004_wrist_x_rot_Coll.dae</uri>
						<scale>1.0 1.0 1.0</scale>
					</mesh>
				</geometry>
			</collision>
			<visual name="VIS_hollhollie_004_wrist_x_rot">
				<pose>-2.2771160956835956e-07 6.274480597312504e-07 -5.625604160286457e-08 2.0264969862182625e-06 -2.2016463390173158e-06 -1.1550821454875404e-07</pose>
				<geometry>
					<mesh>
						<uri>model://google_grasp/meshes/visual/VIS_hollhollie_004_wrist_x_rot.dae</uri>
						<scale>1.0 1.0 1.0</scale>
					</mesh>
				</geometry>
			</visual>
		</link>
<!--arm_6-->
		<link name="hollie_005">
			<pose>-0.005237775420036867 -0.40026984862109644 1.7650000005948487 4.019007348745999e-14 -2.384185794926808e-07 -1.518436702089857</pose>
			<inertial>
				<mass>0.819</mass>
				<pose>0.0 0.0 0.0 0.0 0.0 0.0</pose>
				<inertia>
					<ixx>0.01</ixx>
					<ixy>0.0</ixy>
					<ixz>0.0</ixz>
					<iyy>0.01</iyy>
					<iyz>0.0</iyz>
					<izz>0.01</izz>
				</inertia>
			</inertial>
			<collision name="VIS_hollhollie_005_Coll">
				<pose>-7.496467446799215e-08 4.749598190301185e-07 1.7147423250207794e-06 1.4999766762002764e-08 8.693253761293818e-08 4.172325134277344e-07</pose>
				<geometry>
					<mesh>
						<uri>model://google_grasp/meshes/visual/VIS_hollhollie_005_Coll.dae</uri>
						<scale>1.0 1.0 1.0</scale>
					</mesh>
				</geometry>
			</collision>
			<visual name="VIS_hollhollie_005">
				<pose>-7.650720590390847e-08 4.460888476387481e-07 1.5955330354699981e-06 2.4900401740524103e-08 8.122043482217123e-08 4.172325134277344e-07</pose>
				<geometry>
					<mesh>
						<uri>model://google_grasp/meshes/visual/VIS_hollhollie_005.dae</uri>
						<scale>1.0 1.0 1.0</scale>
					</mesh>
				</geometry>
			</visual>
		</link>
<!--hand_base-->
		<link name="hollie_006_wrist_lat_rot">
			<pose>-0.005237776667821313 -0.4002698248119125 1.865000002084962 4.019007348745999e-14 -2.384185794926808e-07 -1.518436702089857</pose>
			<inertial>
				<mass>0.00001</mass>
				<pose>0.0 0.0 0.0 0.0 0.0 0.0</pose>
				<inertia>
					<ixx>0.01</ixx>
					<ixy>0.0</ixy>
					<ixz>0.0</ixz>
					<iyy>0.01</iyy>
					<iyz>0.0</iyz>
					<izz>0.01</izz>
				</inertia>
			</inertial>
			<collision name="VIS_hollhollie_006_wrist_lat_rot_Coll">
				<pose>-2.173159145968384e-07 9.399680607202754e-07 -0.03199787437915802 -1.4374420231888507e-07 7.949097380333114e-08 -3.054737760521675e-07</pose>
				<geometry>
					<mesh>
						<uri>model://google_grasp/meshes/visual/VIS_hollhollie_006_wrist_lat_rot_Coll.dae</uri>
						<scale>1.0 1.0 1.0</scale>
					</mesh>
				</geometry>
			</collision>
			<visual name="VIS_hollhollie_006_wrist_lat_rot">
				<pose>-2.174905375795788e-07 9.367084317091212e-07 -0.03199787437915802 -1.412941230682918e-07 8.084922598072808e-08 -3.054737760521675e-07</pose>
				<geometry>
					<mesh>
						<uri>model://google_grasp/meshes/visual/VIS_hollhollie_006_wrist_lat_rot.dae</uri>
						<scale>1.0 1.0 1.0</scale>
					</mesh>
				</geometry>
			</visual>
		</link>
<!--arm_7-->
		<link name="hollie_007_wrist_lat_rot">
			<pose>-0.01834778092995153 -0.4009597369285917 1.8650000020856399 4.019007348745999e-14 -2.384185794926808e-07 -1.518436702089857</pose>
			<inertial>
				<mass>0.00001</mass>
				<pose>0.0 0.0 0.0 0.0 0.0 0.0</pose>
				<inertia>
					<ixx>0.01</ixx>
					<ixy>0.0</ixy>
					<ixz>0.0</ixz>
					<iyy>0.01</iyy>
					<iyz>0.0</iyz>
					<izz>0.01</izz>
				</inertia>
			</inertial>
			<collision name="VIS_hollhollie_007_wrist_lat_rot_Coll">
				<pose>-1.158055340511055e-07 0.013130211271345615 2.311210437255795e-06 3.141590118408203 3.028529533821711e-07 -7.860362529754639e-07</pose>
				<geometry>
					<mesh>
						<uri>model://google_grasp/meshes/visual/VIS_hollhollie_007_wrist_lat_rot_Coll.dae</uri>
						<scale>1.0 1.0 1.0</scale>
					</mesh>
				</geometry>
			</collision>
			<visual name="VIS_hollhollie_007_wrist_lat_rot">
				<pose>-8.277268648271274e-08 0.01313027087599039 2.3112102098821197e-06 3.141590118408203 3.1224195140566735e-07 -7.860362529754639e-07</pose>
				<geometry>
					<mesh>
						<uri>model://google_grasp/meshes/visual/VIS_hollhollie_007_wrist_lat_rot.dae</uri>
						<scale>1.0 1.0 1.0</scale>
					</mesh>
				</geometry>
			</visual>
		</link>
		<link name="hollie_008_thumb_lat_rot">
			<pose>0.008732115699361751 -0.4164599182699748 1.8650000061140053 -2.4682907679780766e-07 0.2617993950843437 0.05235960453236189</pose>
			<inertial>
				<mass>9.999999747378752e-06</mass>
				<pose>2.7008354663848877e-08 2.867356556635059e-07 -1.8300488591194153e-07 -2.3959046302479692e-08 -9.05128985095871e-08 -9.686764279592808e-09</pose>
				<inertia>
					<ixx>0.009999999776482582</ixx>
					<ixy>0.0</ixy>
					<ixz>0.0</ixz>
					<iyy>0.009999999776482582</iyy>
					<iyz>0.0</iyz>
					<izz>0.009999999776482582</izz>
				</inertia>
			</inertial>
			<collision name="VIS_hollhollie_008_thumb_lat_rot_Coll">
				<pose>3.4924596548080444e-07 -7.616318953296286e-07 0.024418560788035393 -2.9744596758973785e-06 3.141587257385254 -3.1165795917331707e-06</pose>
				<geometry>
					<mesh>
						<uri>model://google_grasp/meshes/visual/VIS_hollhollie_008_thumb_lat_rot_Coll.dae</uri>
						<scale>1.0 0.9999998807907104 1.0000001192092896</scale>
					</mesh>
				</geometry>
			</collision>
			<visual name="VIS_hollhollie_008_thumb_lat_rot">
				<pose>3.2316893339157104e-07 -8.166963425537688e-07 0.02441829815506935 -2.7868431971000973e-06 3.141587734222412 -2.591313659650041e-06</pose>
				<geometry>
					<mesh>
						<uri>model://google_grasp/meshes/visual/VIS_hollhollie_008_thumb_lat_rot.dae</uri>
						<scale>1.0 0.9999999403953552 1.0000001192092896</scale>
					</mesh>
				</geometry>
			</visual>
		</link>
		<link name="hand_Thumb_Helper_link">
			<pose>0.02061253208036095 -0.4158398898004906 1.9093898952949548 3.1415918834072234 -1.3089968562125396 0.05236055820638709</pose>
			<inertial>
				<mass>9.999999747378752e-06</mass>
				<pose>1.2549571692943573e-07 -1.9744038581848145e-07 -1.4901161193847656e-07 7.078052277620372e-08 1.4156101713069802e-07 1.4342366227992898e-07</pose>
				<inertia>
					<ixx>0.009999999776482582</ixx>
					<ixy>0.0</ixy>
					<ixz>0.0</ixz>
					<iyy>0.009999999776482582</iyy>
					<iyz>0.0</iyz>
					<izz>0.009999999776482582</izz>
				</inertia>
			</inertial>
		</link>
		<link name="hollie_009_thumb_base_rot">
			<pose>0.020612532080360953 -0.4158398898004907 1.9093898952949546 -1.8834040683581643 -0.5706021143657831 -1.3456026096163374</pose>
			<inertial>
				<mass>9.999999747378752e-06</mass>
				<pose>9.313225746154785e-10 0.0017385947285220027 -6.51925802230835e-08 -1.4156105976326216e-07 4.8894428061885264e-08 2.4400648612754594e-07</pose>
				<inertia>
					<ixx>0.009999999776482582</ixx>
					<ixy>0.0</ixy>
					<ixz>0.0</ixz>
					<iyy>0.009999999776482582</iyy>
					<iyz>0.0</iyz>
					<izz>0.009999999776482582</izz>
				</inertia>
			</inertial>
			<collision name="VIS_hollhollie_009_thumb_base_rot_Coll">
				<pose>1.1622905731201172e-06 0.0005107243778184056 -2.998858690261841e-07 -3.141589403152466 6.38887001969124e-07 1.0300423127773684e-06</pose>
				<geometry>
					<mesh>
						<uri>model://google_grasp/meshes/visual/VIS_hollhollie_009_thumb_base_rot_Coll.dae</uri>
						<scale>1.0000004768371582 0.9999999403953552 1.0000003576278687</scale>
					</mesh>
				</geometry>
			</collision>
			<visual name="VIS_hollhollie_009_thumb_base_rot">
				<pose>1.2926757335662842e-06 0.0005106051685288548 -2.7567148208618164e-07 -3.1415903568267822 5.345791578292847e-07 9.872019290924072e-07</pose>
				<geometry>
					<mesh>
						<uri>model://google_grasp/meshes/visual/VIS_hollhollie_009_thumb_base_rot.dae</uri>
						<scale>1.0 0.9999999403953552 1.0000001192092896</scale>
					</mesh>
				</geometry>
			</visual>
		</link>
		<link name="hollie_010_thumb_tip_rot">
			<pose>0.029737260609411877 -0.455629063332385 1.935596027156718 -1.8834040338461981 -0.5706019479941505 -1.3456026735109625</pose>
			<inertial>
				<mass>9.999999747378752e-06</mass>
				<pose>2.852175384759903e-08 2.8258422389626503e-05 -9.592622518539429e-08 6.426126475389538e-08 2.9802318834981634e-08 2.2351738238057806e-08</pose>
				<inertia>
					<ixx>0.009999999776482582</ixx>
					<ixy>0.0</ixy>
					<ixz>0.0</ixz>
					<iyy>0.009999999776482582</iyy>
					<iyz>0.0</iyz>
					<izz>0.009999999776482582</izz>
				</inertia>
			</inertial>
			<collision name="VIS_hollhollie_010_thumb_Coll">
				<pose>-6.242771632969379e-07 7.313676178455353e-06 4.880130290985107e-07 3.1415908336639404 1.601873833578793e-07 1.7844130297817173e-06</pose>
				<geometry>
					<mesh>
						<uri>model://google_grasp/meshes/visual/VIS_hollhollie_010_thumb_Coll.dae</uri>
						<scale>1.0000004768371582 1.0 1.0000004768371582</scale>
					</mesh>
				</geometry>
			</collision>
			<visual name="VIS_hollhollie_010_thumb">
				<pose>-6.284681148827076e-07 7.209600880742073e-06 5.755573511123657e-07 3.1415903568267822 4.88012915411673e-07 2.1047885638836306e-06</pose>
				<geometry>
					<mesh>
						<uri>model://google_grasp/meshes/visual/VIS_hollhollie_010_thumb.dae</uri>
						<scale>1.0000001192092896 0.9999998807907104 1.0000001192092896</scale>
					</mesh>
				</geometry>
			</visual>
		</link>
		<link name="hollie_011_thumb_topsegment_bf_rot">
			<pose>0.03536718786328801 -0.4802390480892404 1.9517960766763784 1.8834040040418392 0.5706018043163879 1.7959899248997433</pose>
			<inertial>
				<mass>9.999999747378752e-06</mass>
				<pose>0.03537106513977051 -0.48023760318756104 1.9517898559570312 -1.8833998441696167 -0.5706019997596741 -1.3456000089645386</pose>
				<inertia>
					<ixx>0.009999999776482582</ixx>
					<ixy>0.0</ixy>
					<ixz>0.0</ixz>
					<iyy>0.009999999776482582</iyy>
					<iyz>0.0</iyz>
					<izz>0.009999999776482582</izz>
				</inertia>
			</inertial>
			<collision name="VIS_hollhollie_011_thumb_topsegment_bf_rot_Coll">
				<pose>-1.590524334460497e-07 3.150198608636856e-07 -6.146728992462158e-08 3.1415910720825195 4.3958405626653985e-07 1.4714889857714297e-06</pose>
				<geometry>
					<mesh>
						<uri>model://google_grasp/meshes/visual/VIS_hollhollie_011_thumb_topsegment_bf_rot_Coll.dae</uri>
						<scale>1.0000004768371582 1.0000001192092896 1.0000005960464478</scale>
					</mesh>
				</geometry>
			</collision>
			<visual name="VIS_hollhollie_011_thumb_topsegment_bf_rot">
				<pose>-3.974710125476122e-07 2.9639340937137604e-07 -5.029141902923584e-08 3.141589879989624 2.3283067207557906e-07 2.0749869236169616e-06</pose>
				<geometry>
					<mesh>
						<uri>model://google_grasp/meshes/visual/VIS_hollhollie_011_thumb_topsegment_bf_rot.dae</uri>
						<scale>0.9999998807907104 0.9999997019767761 1.000000238418579</scale>
					</mesh>
				</geometry>
			</visual>
		</link>
		<link name="hand_f1_link">
			<pose>-0.01834778092995154 -0.40095973692859166 1.8650000020856399 4.019007348745999e-14 -2.384185794926808e-07 -1.518436702089857</pose>
			<inertial>
				<mass>9.999999747378752e-06</mass>
				<pose>-3.274359983151953e-08 6.951387376830098e-08 2.8465240120567614e-07 -2.288598320186394e-14 -1.315614114774221e-14 -7.450581307466564e-08</pose>
				<inertia>
					<ixx>0.009999999776482582</ixx>
					<ixy>0.0</ixy>
					<ixz>0.0</ixz>
					<iyy>0.009999999776482582</iyy>
					<iyz>0.0</iyz>
					<izz>0.009999999776482582</izz>
				</inertia>
			</inertial>
		</link>
		<link name="hand_f2_link">
			<pose>-0.01834778092995155 -0.4009597369285916 1.8650000020856399 4.019007348745999e-14 -2.384185794926808e-07 -1.518436702089857</pose>
			<inertial>
				<mass>9.999999747378752e-06</mass>
				<pose>-2.674826760085125e-08 1.8313522787138936e-07 1.654431116548949e-07 -8.231040970877769e-15 -1.3267163450204726e-14 -7.450581307466564e-08</pose>
				<inertia>
					<ixx>0.009999999776482582</ixx>
					<ixy>0.0</ixy>
					<ixz>0.0</ixz>
					<iyy>0.009999999776482582</iyy>
					<iyz>0.0</iyz>
					<izz>0.009999999776482582</izz>
				</inertia>
			</inertial>
		</link>
		<link name="hand_f3_link">
			<pose>-0.01834778092995156 -0.40095973692859155 1.8650000020856399 4.019007348745999e-14 -2.384185794926808e-07 -1.518436702089857</pose>
			<inertial>
				<mass>9.999999747378752e-06</mass>
				<pose>-3.303472340121516e-08 6.392594542603547e-08 1.654431116548949e-07 -7.342863398210591e-15 9.436894650522647e-16 -7.450581307466564e-08</pose>
				<inertia>
					<ixx>0.009999999776482582</ixx>
					<ixy>0.0</ixy>
					<ixz>0.0</ixz>
					<iyy>0.009999999776482582</iyy>
					<iyz>0.0</iyz>
					<izz>0.009999999776482582</izz>
				</inertia>
			</inertial>
		</link>
		<link name="hollie_012_indexfing_lr_rot">
			<pose>-0.017037949611288718 -0.4259197190488656 1.9750000074487084 -1.5707965297684179 -1.5707961638742167 1.6231561981848475</pose>
			<inertial>
				<mass>9.999999747378752e-06</mass>
				<pose>-1.6393606472320243e-07 -2.2042723912818474e-07 1.630180435086004e-08 3.7252894102834944e-09 1.2568585816552513e-07 -1.8276516300375079e-07</pose>
				<inertia>
					<ixx>0.009999999776482582</ixx>
					<ixy>0.0</ixy>
					<ixz>0.0</ixz>
					<iyy>0.009999999776482582</iyy>
					<iyz>0.0</iyz>
					<izz>0.009999999776482582</izz>
				</inertia>
			</inertial>
			<collision name="VIS_hollhollie_012_indexfing_lr_rot_Coll">
				<pose>7.594572082325612e-08 -6.20721380073519e-07 0.013210223987698555 7.078048724906694e-08 3.637777012954757e-07 -1.9524297556472447e-07</pose>
				<geometry>
					<mesh>
						<uri>model://google_grasp/meshes/visual/VIS_hollhollie_012_indexfing_lr_rot_Coll.dae</uri>
						<scale>1.0 1.000000238418579 1.0</scale>
					</mesh>
				</geometry>
			</collision>
			<visual name="VIS_hollhollie_012_indexfing_lr_rot">
				<pose>7.594572792868348e-08 -5.015120905227377e-07 0.013210218399763107 7.450579175838357e-08 3.637777012954757e-07 -1.9524297556472447e-07</pose>
				<geometry>
					<mesh>
						<uri>model://google_grasp/meshes/visual/VIS_hollhollie_012_indexfing_lr_rot.dae</uri>
						<scale>1.0 1.0000001192092896 1.0</scale>
					</mesh>
				</geometry>
			</visual>
		</link>
		<link name="hollie_013_indexfing_bf_rot">
			<pose>-0.017037949611288718 -0.4259197190488656 1.9750000074487086 3.141592406904882 -1.5707961638742167 1.6231561981848475</pose>
			<inertial>
				<mass>9.999999747378752e-06</mass>
				<pose>1.6926779267123493e-07 1.672655116635724e-07 -8.407144491684448e-08 1.1175875158642157e-07 2.3370756707663531e-07 1.3483571592587396e-07</pose>
				<inertia>
					<ixx>0.009999999776482582</ixx>
					<ixy>0.0</ixy>
					<ixz>0.0</ixz>
					<iyy>0.009999999776482582</iyy>
					<iyz>0.0</iyz>
					<izz>0.009999999776482582</izz>
				</inertia>
			</inertial>
			<collision name="VIS_hollhollie_013_indexfing_bf_rot_Coll">
				<pose>-4.267786550826713e-07 3.2186508747145126e-07 -1.2208090538479155e-07 -2.868473075068323e-06 2.2746866079614847e-07 1.5789797913612347e-08</pose>
				<geometry>
					<mesh>
						<uri>model://google_grasp/meshes/visual/VIS_hollhollie_013_indexfing_bf_rot_Coll.dae</uri>
						<scale>1.0 1.0000001192092896 1.000000238418579</scale>
					</mesh>
				</geometry>
			</collision>
			<visual name="VIS_hollhollie_013_indexfing_bf_rot">
				<pose>-4.267786550826713e-07 2.0638108821913193e-07 -5.624804089165991e-08 -2.749264012891217e-06 2.2746866079614847e-07 1.5789797913612347e-08</pose>
				<geometry>
					<mesh>
						<uri>model://google_grasp/meshes/visual/VIS_hollhollie_013_indexfing_bf_rot.dae</uri>
						<scale>1.0 1.0000001192092896 1.0000001192092896</scale>
					</mesh>
				</geometry>
			</visual>
		</link>
		<link name="hollie_014_indexfing_midsegment_bf_rot">
			<pose>-0.017037934199257015 -0.425910014755747 2.0230400063062977 3.141592406904882 -1.5707961638742167 1.6231561981848475</pose>
			<inertial>
				<mass>9.999999747378752e-06</mass>
				<pose>-5.459863814394339e-07 -8.82388917489152e-09 -1.4202601050783414e-07 4.470351910867976e-08 2.337075528657806e-07 1.3483570171501924e-07</pose>
				<inertia>
					<ixx>0.009999999776482582</ixx>
					<ixy>0.0</ixy>
					<ixz>0.0</ixz>
					<iyy>0.009999999776482582</iyy>
					<iyz>0.0</iyz>
					<izz>0.009999999776482582</izz>
				</inertia>
			</inertial>
			<collision name="VIS_hollhollie_014_indexfing_midsegment_bf_rot_Coll">
				<pose>-3.0756777391616197e-07 -4.85661075799726e-07 -1.7683424857750651e-07 -2.9355287551879883e-06 2.337075528657806e-07 1.3483570171501924e-07</pose>
				<geometry>
					<mesh>
						<uri>model://google_grasp/meshes/visual/VIS_hollhollie_014_indexfing_midsegment_bf_rot_Coll.dae</uri>
						<scale>1.0 1.0 1.0</scale>
					</mesh>
				</geometry>
			</collision>
			<visual name="VIS_hollhollie_014_indexfing_midsegment_bf_rot">
				<pose>-3.0756777391616197e-07 -4.260564310243353e-07 -1.500587245573115e-07 -3.0547375899914186e-06 2.2746864658529375e-07 1.578978903182815e-08</pose>
				<geometry>
					<mesh>
						<uri>model://google_grasp/meshes/visual/VIS_hollhollie_014_indexfing_midsegment_bf_rot.dae</uri>
						<scale>1.0 1.0000001192092896 1.0000001192092896</scale>
					</mesh>
				</geometry>
			</visual>
		</link>
		<link name="hollie_015_indexfing_topsegment_bf_rot">
			<pose>-0.017037925811464016 -0.4259101747968256 2.049040006842766 3.141592406904882 -1.5707961638742167 1.6231561981848475</pose>
			<inertial>
				<mass>9.999999747378752e-06</mass>
				<pose>-5.459863814394339e-07 7.104930773493834e-06 -7.272370794453309e-08 4.097823236293152e-08 2.3370752444407117e-07 1.3483570171501924e-07</pose>
				<inertia>
					<ixx>0.009999999776482582</ixx>
					<ixy>0.0</ixy>
					<ixz>0.0</ixz>
					<iyy>0.009999999776482582</iyy>
					<iyz>0.0</iyz>
					<izz>0.009999999776482582</izz>
				</inertia>
			</inertial>
			<collision name="VIS_hollhollie_015_indexfing_topsegment_bf_rot_Coll">
				<pose>-5.459864382828528e-07 7.211101546999998e-06 -4.967083100382297e-07 -2.7008347842638614e-06 2.2746861816358432e-07 1.578979258454183e-08</pose>
				<geometry>
					<mesh>
						<uri>model://google_grasp/meshes/visual/VIS_hollhollie_015_indexfing_topsegment_bf_rot_Coll.dae</uri>
						<scale>1.0000001192092896 1.0000001192092896 1.000000238418579</scale>
					</mesh>
				</geometry>
			</collision>
			<visual name="VIS_hollhollie_015_indexfing_topsegment_bf_rot">
				<pose>-5.459864382828528e-07 7.151496902224608e-06 -4.6370456630029366e-07 -2.8200440738146426e-06 2.2746861816358432e-07 1.578979258454183e-08</pose>
				<geometry>
					<mesh>
						<uri>model://google_grasp/meshes/visual/VIS_hollhollie_015_indexfing_topsegment_bf_rot.dae</uri>
						<scale>1.0000001192092896 1.0000001192092896 1.0000001192092896</scale>
					</mesh>
				</geometry>
			</visual>
		</link>
		<link name="hollie_016_midfing_lr_rot">
			<pose>-0.018347782302514413 -0.4009597107384898 1.9750000014895903 -1.5707965297684179 -1.5707961638742167 1.6231561981848475</pose>
			<inertial>
				<mass>9.999999747378752e-06</mass>
				<pose>-1.5961779809003929e-07 -2.0542805145851162e-07 -6.049923229056731e-09 3.7252889661942845e-09 2.447317797305004e-07 -1.29399424508847e-07</pose>
				<inertia>
					<ixx>0.009999999776482582</ixx>
					<ixy>0.0</ixy>
					<ixz>0.0</ixz>
					<iyy>0.009999999776482582</iyy>
					<iyz>0.0</iyz>
					<izz>0.009999999776482582</izz>
				</inertia>
			</inertial>
			<collision name="VIS_hollhollie_016_midfing_lr_rot_Coll">
				<pose>-3.96573256011834e-07 -1.3887315617466811e-06 0.013210099190473557 1.3038510360274813e-07 3.6377772971718514e-07 -1.3563833078933385e-07</pose>
				<geometry>
					<mesh>
						<uri>model://google_grasp/meshes/visual/VIS_hollhollie_016_midfing_lr_rot_Coll.dae</uri>
						<scale>1.0 1.0000003576278687 1.0</scale>
					</mesh>
				</geometry>
			</collision>
			<visual name="VIS_hollhollie_016_midfing_lr_rot">
				<pose>-3.96573256011834e-07 -1.3286612556839827e-06 0.013210102915763855 1.3038511781360285e-07 3.6377772971718514e-07 -1.3563833078933385e-07</pose>
				<geometry>
					<mesh>
						<uri>model://google_grasp/meshes/visual/VIS_hollhollie_016_midfing_lr_rot.dae</uri>
						<scale>1.0 1.000000238418579 1.0</scale>
					</mesh>
				</geometry>
			</visual>
		</link>
		<link name="hollie_017_midfing_bf_rot">
			<pose>-0.018347782302514402 -0.40095971073848974 1.9750000014895903 3.141592406904882 -1.5707961638742167 1.6231561981848475</pose>
			<inertial>
				<mass>9.999999747378752e-06</mass>
				<pose>5.5558430744895304e-08 2.417712607893918e-07 -2.2437026814259298e-07 -7.078048014363958e-08 1.7410290809038997e-07 1.3483570171501924e-07</pose>
				<inertia>
					<ixx>0.009999999776482582</ixx>
					<ixy>0.0</ixy>
					<ixz>0.0</ixz>
					<iyy>0.009999999776482582</iyy>
					<iyz>0.0</iyz>
					<izz>0.009999999776482582</izz>
				</inertia>
			</inertial>
			<collision name="VIS_hollhollie_017_midfing_bf_rot_Coll">
				<pose>-6.365097249272367e-08 4.205852235372731e-07 -9.509182632427837e-07 5.252659320831299e-07 1.6786401602075784e-07 1.5789801466326026e-08</pose>
				<geometry>
					<mesh>
						<uri>model://google_grasp/meshes/visual/VIS_hollhollie_017_midfing_bf_rot_Coll.dae</uri>
						<scale>1.0 1.0 1.000000238418579</scale>
					</mesh>
				</geometry>
			</collision>
			<visual name="VIS_hollhollie_017_midfing_bf_rot">
				<pose>-6.365096538729631e-08 3.6284322391111345e-07 -9.179727271657612e-07 4.0978196125252e-07 1.7410290809038997e-07 1.3483570171501924e-07</pose>
				<geometry>
					<mesh>
						<uri>model://google_grasp/meshes/visual/VIS_hollhollie_017_midfing_bf_rot.dae</uri>
						<scale>1.0 1.0 1.000000238418579</scale>
					</mesh>
				</geometry>
			</visual>
		</link>
		<link name="hollie_018_midfing_midsegment_bf_rot">
			<pose>-0.018347766245290404 -0.40095001875643466 2.025040000675007 3.141592406904882 -1.5707961638742167 1.6231561981848475</pose>
			<inertial>
				<mass>9.999999747378752e-06</mass>
				<pose>-6.364928850643992e-08 8.21796504624217e-07 -2.9082713126626913e-08 4.0978221704790485e-08 1.7410290809038997e-07 1.3483568750416453e-07</pose>
				<inertia>
					<ixx>0.009999999776482582</ixx>
					<ixy>0.0</ixy>
					<ixz>0.0</ixz>
					<iyy>0.009999999776482582</iyy>
					<iyz>0.0</iyz>
					<izz>0.009999999776482582</izz>
				</inertia>
			</inertial>
			<collision name="VIS_hollhollie_018_midfing_midsegment_bf_rot_Coll">
				<pose>-1.4941608696972253e-06 1.4625464928030851e-06 -4.810649443243165e-07 -7.823101810799926e-08 1.8658070644050895e-07 3.729275306341151e-07</pose>
				<geometry>
					<mesh>
						<uri>model://google_grasp/meshes/visual/VIS_hollhollie_018_midfing_midsegment_bf_rot_Coll.dae</uri>
						<scale>1.0 1.0 1.0000003576278687</scale>
					</mesh>
				</geometry>
			</collision>
			<visual name="VIS_hollhollie_018_midfing_midsegment_bf_rot">
				<pose>-1.4941608696972253e-06 1.4588212025046232e-06 -4.510298197146767e-07 -7.823101810799926e-08 1.8658070644050895e-07 3.729275306341151e-07</pose>
				<geometry>
					<mesh>
						<uri>model://google_grasp/meshes/visual/VIS_hollhollie_018_midfing_midsegment_bf_rot.dae</uri>
						<scale>1.0 1.0 1.000000238418579</scale>
					</mesh>
				</geometry>
			</visual>
		</link>
		<link name="hollie_019_midfing_topsegment_bf_rot">
			<pose>-0.01834775592185265 -0.400950215730074 2.0570400021949578 3.141592406904882 -1.5707961638742167 1.6231561981848475</pose>
			<inertial>
				<mass>9.999999747378752e-06</mass>
				<pose>-6.364933824443142e-08 6.456253231590381e-06 -1.2073655852873344e-07 4.0978221704790485e-08 1.7410290809038997e-07 1.3483571592587396e-07</pose>
				<inertia>
					<ixx>0.009999999776482582</ixx>
					<ixy>0.0</ixy>
					<ixz>0.0</ixz>
					<iyy>0.009999999776482582</iyy>
					<iyz>0.0</iyz>
					<izz>0.009999999776482582</izz>
				</inertia>
			</inertial>
			<collision name="VIS_hollhollie_019_midfing_topsegment_bf_rot_Coll">
				<pose>-6.364945193126914e-08 6.296065748756519e-06 -8.892523055692436e-07 -4.358589080766251e-07 1.803418001600221e-07 2.538816090691398e-07</pose>
				<geometry>
					<mesh>
						<uri>model://google_grasp/meshes/visual/VIS_hollhollie_019_midfing_topsegment_bf_rot_Coll.dae</uri>
						<scale>1.0 1.0 1.0000003576278687</scale>
					</mesh>
				</geometry>
			</collision>
			<visual name="VIS_hollhollie_019_midfing_topsegment_bf_rot">
				<pose>-6.364945193126914e-08 6.294203103607288e-06 -8.891358902474167e-07 -4.358589080766251e-07 1.803418001600221e-07 2.538816090691398e-07</pose>
				<geometry>
					<mesh>
						<uri>model://google_grasp/meshes/visual/VIS_hollhollie_019_midfing_topsegment_bf_rot.dae</uri>
						<scale>1.0 1.0 1.000000238418579</scale>
					</mesh>
				</geometry>
			</visual>
		</link>
		<link name="hollie_020_outerhand_rot">
			<pose>-0.013317655931604028 -0.38226976163570303 1.9024999991885916 4.019007348745999e-14 -2.384185794926808e-07 -1.518436702089857</pose>
			<inertial>
				<mass>9.999999747378752e-06</mass>
				<pose>-8.293628184219415e-08 -1.916289704695373e-07 4.9595520579259755e-08 2.6606377101501266e-09 2.190845505012362e-09 -7.450581307466564e-08</pose>
				<inertia>
					<ixx>0.009999999776482582</ixx>
					<ixy>0.0</ixy>
					<ixz>0.0</ixz>
					<iyy>0.009999999776482582</iyy>
					<iyz>0.0</iyz>
					<izz>0.009999999776482582</izz>
				</inertia>
			</inertial>
			<collision name="VIS_hollhollie_020_outerhand_rot_Coll">
				<pose>0.0006994588184170425 9.115898080835905e-08 -0.010019372217357159 3.141590118408203 3.158701389338603e-08 -4.3213361777816317e-07</pose>
				<geometry>
					<mesh>
						<uri>model://google_grasp/meshes/visual/VIS_hollhollie_020_outerhand_rot_Coll.dae</uri>
						<scale>1.0 0.9999999403953552 1.0</scale>
					</mesh>
				</geometry>
			</collision>
			<visual name="VIS_hollhollie_020_outerhand_rot">
				<pose>0.0006994916475377977 1.4703833528528776e-07 -0.010019372217357159 3.141590118408203 3.3524806042350974e-08 -4.3213361777816317e-07</pose>
				<geometry>
					<mesh>
						<uri>model://google_grasp/meshes/visual/VIS_hollhollie_020_outerhand_rot.dae</uri>
						<scale>1.0 0.9999999403953552 1.0</scale>
					</mesh>
				</geometry>
			</visual>
		</link>
		<link name="hand_f5_link">
			<pose>-0.01931765819272022 -0.3825797214327669 1.9024999991875233 4.019007348745999e-14 -2.384185794926808e-07 -1.518436702089857</pose>
			<inertial>
				<mass>9.999999747378752e-06</mass>
				<pose>3.312979401925986e-08 1.0639425340741582e-07 1.688055988324777e-07 3.0314502019734846e-09 9.26851839722076e-09 -7.450580596923828e-08</pose>
				<inertia>
					<ixx>0.009999999776482582</ixx>
					<ixy>0.0</ixy>
					<ixz>0.0</ixz>
					<iyy>0.009999999776482582</iyy>
					<iyz>0.0</iyz>
					<izz>0.009999999776482582</izz>
				</inertia>
			</inertial>
		</link>
		<link name="hand_f6_link">
			<pose>-0.01931765819272022 -0.3825797214327669 1.9024999991875233 4.019007348745999e-14 -2.384185794926808e-07 -1.518436702089857</pose>
			<inertial>
				<mass>9.999999747378752e-06</mass>
				<pose>2.5911987222571042e-08 -3.1441480530247645e-08 4.9596319939837485e-08 2.6605988523442647e-09 2.190875481034027e-09 4.8428763221863846e-08</pose>
				<inertia>
					<ixx>0.009999999776482582</ixx>
					<ixy>0.0</ixy>
					<ixz>0.0</ixz>
					<iyy>0.009999999776482582</iyy>
					<iyz>0.0</iyz>
					<izz>0.009999999776482582</izz>
				</inertia>
			</inertial>
		</link>
		<link name="hand_f7_link">
			<pose>-0.01931765819272022 -0.3825797214327669 1.9024999991875233 4.019007348745999e-14 -2.384185794926808e-07 -1.518436702089857</pose>
			<inertial>
				<mass>9.999999747378752e-06</mass>
				<pose>-3.657532943179831e-09 -2.3990899933323817e-08 4.95963341506922e-08 2.6606210568047572e-09 2.190875258989422e-09 4.470347292340193e-08</pose>
				<inertia>
					<ixx>0.009999999776482582</ixx>
					<ixy>0.0</ixy>
					<ixz>0.0</ixz>
					<iyy>0.009999999776482582</iyy>
					<iyz>0.0</iyz>
					<izz>0.009999999776482582</izz>
				</inertia>
			</inertial>
		</link>
		<link name="hollie_021_littlefinger_lr_rot">
			<pose>-0.0206374892091288 -0.3572596989773305 1.9584999948711004 1.5707961556078849 -1.5707961638742167 1.6231561981848475</pose>
			<inertial>
				<mass>9.999999747378752e-06</mass>
				<pose>-1.8930045087017788e-07 7.110531896614702e-08 -1.1067186278523877e-08 0.030488917604088783 -1.3359593822315219e-06 2.794857891785796e-07</pose>
				<inertia>
					<ixx>0.009999999776482582</ixx>
					<ixy>0.0</ixy>
					<ixz>0.0</ixz>
					<iyy>0.009999999776482582</iyy>
					<iyz>0.0</iyz>
					<izz>0.009999999776482582</izz>
				</inertia>
			</inertial>
			<collision name="VIS_hollhollie_021_littlefinger_lr_rot_Coll">
				<pose>-4.3700671881197195e-07 -1.467905349272769e-06 -0.013210128992795944 0.38753741979599 -2.6407732889310864e-07 2.326765695670474e-07</pose>
				<geometry>
					<mesh>
						<uri>model://google_grasp/meshes/visual/VIS_hollhollie_021_littlefinger_lr_rot_Coll.dae</uri>
						<scale>1.0 0.9999998807907104 0.9999997615814209</scale>
					</mesh>
				</geometry>
			</collision>
			<visual name="VIS_hollhollie_021_littlefinger_lr_rot">
				<pose>-4.3700671881197195e-07 -1.4673232726636343e-06 -0.013210117816925049 0.3875378966331482 -9.783528867046698e-07 2.7011009251509677e-07</pose>
				<geometry>
					<mesh>
						<uri>model://google_grasp/meshes/visual/VIS_hollhollie_021_littlefinger_lr_rot.dae</uri>
						<scale>1.0 0.9999998211860657 0.9999998211860657</scale>
					</mesh>
				</geometry>
			</visual>
		</link>
		<link name="hollie_022_littlefinger_bf_rot">
			<pose>-0.020637489209128793 -0.3572596989773305 1.9584999948711004 3.1415925261141715 -1.5707961638742167 1.6231561981848475</pose>
			<inertial>
				<mass>9.999999747378752e-06</mass>
				<pose>-1.9228880887567357e-07 1.9420735952735413e-07 -4.092245831088803e-08 0.03162764757871628 2.2151192524688668e-07 1.2075265658495482e-06</pose>
				<inertia>
					<ixx>0.009999999776482582</ixx>
					<ixy>0.0</ixy>
					<ixz>0.0</ixz>
					<iyy>0.009999999776482582</iyy>
					<iyz>0.0</iyz>
					<izz>0.009999999776482582</izz>
				</inertia>
			</inertial>
			<collision name="VIS_hollhollie_022_littlefinger_bf_rot_Coll">
				<pose>5.229671273809799e-07 4.6242769258242333e-07 1.8399180135020288e-07 -1.3411033705779118e-07 2.13959694406185e-07 -1.0423630669720296e-07</pose>
				<geometry>
					<mesh>
						<uri>model://google_grasp/meshes/visual/VIS_hollhollie_022_littlefinger_bf_rot_Coll.dae</uri>
						<scale>1.0 0.9999998807907104 0.9999998807907104</scale>
					</mesh>
				</geometry>
			</collision>
			<visual name="VIS_hollhollie_022_littlefinger_bf_rot">
				<pose>6.421764737751801e-07 5.220322236709762e-07 2.4068606307992013e-07 -3.7252877405080653e-07 2.701098651414213e-07 9.67177015809284e-07</pose>
				<geometry>
					<mesh>
						<uri>model://google_grasp/meshes/visual/VIS_hollhollie_022_littlefinger_bf_rot.dae</uri>
						<scale>1.0 0.9999998807907104 0.9999998211860657</scale>
					</mesh>
				</geometry>
			</visual>
		</link>
		<link name="hollie_023_littlefinger_midsegment_bf_rot">
			<pose>-0.020637474927410828 -0.3572499731396248 2.0030399940863135 3.1415925261141715 -1.5707961638742167 1.6231561981848475</pose>
			<inertial>
				<mass>9.999999747378752e-06</mass>
				<pose>-1.0267511925121653e-06 1.314535211349721e-06 -1.0439578090881696e-08 0.02670351415872574 1.0853342757854989e-07 1.4452926961894264e-06</pose>
				<inertia>
					<ixx>0.009999999776482582</ixx>
					<ixy>0.0</ixy>
					<ixz>0.0</ixz>
					<iyy>0.009999999776482582</iyy>
					<iyz>0.0</iyz>
					<izz>0.009999999776482582</izz>
				</inertia>
			</inertial>
			<collision name="VIS_hollhollie_023_littlefinger_midsegment_bf_rot_Coll">
				<pose>-1.9804249404842267e-06 1.9925387277908158e-06 2.5289205041190144e-07 -3.8370481547644886e-07 2.201987285843643e-07 1.480951095089722e-08</pose>
				<geometry>
					<mesh>
						<uri>model://google_grasp/meshes/visual/VIS_hollhollie_023_littlefinger_midsegment_bf_rot_Coll.dae</uri>
						<scale>0.9999999403953552 0.9999998211860657 0.9999998211860657</scale>
					</mesh>
				</geometry>
			</collision>
			<visual name="VIS_hollhollie_023_littlefinger_midsegment_bf_rot">
				<pose>-2.457262326061027e-06 1.8807804735843092e-06 1.3927078157394135e-07 -4.991886157768022e-07 2.701101209368062e-07 9.671769021224463e-07</pose>
				<geometry>
					<mesh>
						<uri>model://google_grasp/meshes/visual/VIS_hollhollie_023_littlefinger_midsegment_bf_rot.dae</uri>
						<scale>0.9999999403953552 0.9999998807907104 0.9999998211860657</scale>
					</mesh>
				</geometry>
			</visual>
		</link>
		<link name="hollie_024_littlefinger_topsegment_bf_rot">
			<pose>-0.020637467830031345 -0.35725010855899053 2.0250399939671264 3.1415925261141715 -1.5707961638742167 1.6231561981848475</pose>
			<inertial>
				<mass>9.999999747378752e-06</mass>
				<pose>-7.883311354817124e-07 3.3314966003672453e-06 -9.800174893825897e-08 0.02670348808169365 1.0853346310568668e-07 1.4452926961894264e-06</pose>
				<inertia>
					<ixx>0.009999999776482582</ixx>
					<ixy>0.0</ixy>
					<ixz>0.0</ixz>
					<iyy>0.009999999776482582</iyy>
					<iyz>0.0</iyz>
					<izz>0.009999999776482582</izz>
				</inertia>
			</inertial>
			<collision name="VIS_hollhollie_024_littlefinger_topsegment_bf_rot_Coll">
				<pose>-1.026750055643788e-06 2.7317250896885525e-06 4.1154814311994414e-07 -5.029141334489395e-07 2.139597796713133e-07 -1.0423635643519447e-07</pose>
				<geometry>
					<mesh>
						<uri>model://google_grasp/meshes/visual/VIS_hollhollie_024_littlefinger_topsegment_bf_rot_Coll.dae</uri>
						<scale>1.0 0.9999998807907104 0.9999998211860657</scale>
					</mesh>
				</geometry>
			</collision>
			<visual name="VIS_hollhollie_024_littlefinger_topsegment_bf_rot">
				<pose>-1.2651686347453506e-06 2.7112362204206875e-06 5.023521225666627e-07 -0.02905253693461418 2.1689443485684023e-07 1.3268505654195906e-06</pose>
				<geometry>
					<mesh>
						<uri>model://google_grasp/meshes/visual/VIS_hollhollie_024_littlefinger_topsegment_bf_rot.dae</uri>
						<scale>1.0 0.9999999403953552 0.9999998211860657</scale>
					</mesh>
				</geometry>
			</visual>
		</link>
		<link name="hand_f8_link">
			<pose>-0.01931765819272022 -0.3825797214327669 1.9024999991875233 4.019007348745999e-14 -2.384185794926808e-07 -1.518436702089857</pose>
			<inertial>
				<mass>9.999999747378752e-06</mass>
				<pose>-3.657532943179831e-09 -2.3990899933323817e-08 4.95963341506922e-08 2.6606210568047572e-09 2.190875258989422e-09 4.470347292340193e-08</pose>
				<inertia>
					<ixx>0.009999999776482582</ixx>
					<ixy>0.0</ixy>
					<ixz>0.0</ixz>
					<iyy>0.009999999776482582</iyy>
					<iyz>0.0</iyz>
					<izz>0.009999999776482582</izz>
				</inertia>
			</inertial>
		</link>
		<link name="hollie_025_ringfinger_lr_rot">
			<pose>-0.019517633209596683 -0.37872970444772575 1.9679999968974655 1.5707961556078849 -1.5707961638742167 1.6231561981848475</pose>
			<inertial>
				<mass>9.999999747378752e-06</mass>
				<pose>-3.1233832942234585e-07 6.62834054310224e-08 1.9451817934168503e-10 0.030399125069379807 -1.34002766571939e-06 2.720516363297065e-07</pose>
				<inertia>
					<ixx>0.009999999776482582</ixx>
					<ixy>0.0</ixy>
					<ixz>0.0</ixz>
					<iyy>0.009999999776482582</iyy>
					<iyz>0.0</iyz>
					<izz>0.009999999776482582</izz>
				</inertia>
			</inertial>
			<collision name="VIS_hollhollie_025_ringfinger_lr_rot_Coll">
				<pose>-2.0236751652191742e-07 -4.77608978144417e-07 -0.01320994645357132 0.1913403868675232 -3.868485123348364e-07 2.3891547584753425e-07</pose>
				<geometry>
					<mesh>
						<uri>model://google_grasp/meshes/visual/VIS_hollhollie_025_ringfinger_lr_rot_Coll.dae</uri>
						<scale>1.0 0.9999998211860657 0.9999997615814209</scale>
					</mesh>
				</geometry>
			</collision>
			<visual name="VIS_hollhollie_025_ringfinger_lr_rot">
				<pose>-2.0236755915448157e-07 -3.905302889961604e-07 -0.0132099948823452 0.16908499598503113 -1.2815315812986228e-06 6.79767993005953e-07</pose>
				<geometry>
					<mesh>
						<uri>model://google_grasp/meshes/visual/VIS_hollhollie_025_ringfinger_lr_rot.dae</uri>
						<scale>1.0 0.9999998211860657 0.9999998211860657</scale>
					</mesh>
				</geometry>
			</visual>
		</link>
		<link name="hollie_026_ringfinger_bf_rot">
			<pose>-0.019517633209596683 -0.37872970444772575 1.9679999968974657 3.1415925261141715 -1.5707961638742167 1.6231561981848475</pose>
			<inertial>
				<mass>9.999999747378752e-06</mass>
				<pose>4.340841996963718e-08 7.326003697016858e-07 5.739053676734329e-09 0.03157386556267738 2.3268820825705916e-07 1.2076031907781726e-06</pose>
				<inertia>
					<ixx>0.009999999776482582</ixx>
					<ixy>0.0</ixy>
					<ixz>0.0</ixz>
					<iyy>0.009999999776482582</iyy>
					<iyz>0.0</iyz>
					<izz>0.009999999776482582</izz>
				</inertia>
			</inertial>
			<collision name="VIS_hollhollie_026_ringfinger_bf_rot_Coll">
				<pose>-7.910563226687373e-07 1.2075755648766062e-06 -5.270936753731803e-07 -0.05260659381747246 2.2262196353040054e-07 -2.232822708947424e-07</pose>
				<geometry>
					<mesh>
						<uri>model://google_grasp/meshes/visual/VIS_hollhollie_026_ringfinger_bf_rot_Coll.dae</uri>
						<scale>1.0 0.9999998211860657 0.9999997019767761</scale>
					</mesh>
				</geometry>
			</collision>
			<visual name="VIS_hollhollie_026_ringfinger_bf_rot">
				<pose>-6.718470899613749e-07 1.1759104836528422e-06 -5.553826554205443e-07 -0.09787814319133759 2.8445293764889357e-07 1.086566498997854e-06</pose>
				<geometry>
					<mesh>
						<uri>model://google_grasp/meshes/visual/VIS_hollhollie_026_ringfinger_bf_rot.dae</uri>
						<scale>1.0 0.9999999403953552 0.9999997615814209</scale>
					</mesh>
				</geometry>
			</visual>
		</link>
		<link name="hollie_027_ringfinger_midsegment_bf_rot">
			<pose>-0.019517617153527088 -0.37872001246566867 2.0180399960828823 3.1415925261141715 -1.5707961638742167 1.6231561981848475</pose>
			<inertial>
				<mass>9.999999747378752e-06</mass>
				<pose>-5.526346171791374e-07 2.20443143916782e-06 -1.0798953553603496e-07 0.02684667333960533 1.3460291370392952e-07 1.4456180679189856e-06</pose>
				<inertia>
					<ixx>0.009999999776482582</ixx>
					<ixy>0.0</ixy>
					<ixz>0.0</ixz>
					<iyy>0.009999999776482582</iyy>
					<iyz>0.0</iyz>
					<izz>0.009999999776482582</izz>
				</inertia>
			</inertial>
			<collision name="VIS_hollhollie_027_ringfinger_midsegment_bf_rot_Coll">
				<pose>-7.910531962806999e-07 2.2845254079584265e-06 -5.006583592148672e-07 -1.2293445195155073e-07 2.3509986135650252e-07 1.4809517168146158e-08</pose>
				<geometry>
					<mesh>
						<uri>model://google_grasp/meshes/visual/VIS_hollhollie_027_ringfinger_midsegment_bf_rot_Coll.dae</uri>
						<scale>1.0 0.9999998807907104 0.9999998807907104</scale>
					</mesh>
				</geometry>
			</collision>
			<visual name="VIS_hollhollie_027_ringfinger_midsegment_bf_rot">
				<pose>-7.910532531241188e-07 2.2305086986307288e-06 -4.978643914910208e-07 -3.613529031554208e-07 2.85011225287235e-07 9.67177015809284e-07</pose>
				<geometry>
					<mesh>
						<uri>model://google_grasp/meshes/visual/VIS_hollhollie_027_ringfinger_midsegment_bf_rot.dae</uri>
						<scale>1.0 0.9999998807907104 0.9999998211860657</scale>
					</mesh>
				</geometry>
			</visual>
		</link>
		<link name="hollie_028_ringfinger_topsegment_bf_rot">
			<pose>-0.019517606830065228 -0.37872020943930673 2.050039997602833 3.1415925261141715 -1.5707961638742167 1.6231561981848475</pose>
			<inertial>
				<mass>9.999999747378752e-06</mass>
				<pose>-5.52634787709394e-07 1.7679907386991545e-06 -6.982020295254188e-08 0.02684665471315384 1.3460294212563895e-07 1.4456181816058233e-06</pose>
				<inertia>
					<ixx>0.009999999776482582</ixx>
					<ixy>0.0</ixy>
					<ixz>0.0</ixz>
					<iyy>0.009999999776482582</iyy>
					<iyz>0.0</iyz>
					<izz>0.009999999776482582</izz>
				</inertia>
			</inertial>
			<collision name="VIS_hollie_028_ringfinger_topsegment_bf_rot_Coll">
				<pose>1.6262079327589163e-07 1.589176235938794e-06 -2.697054526379361e-07 0.020018091425299644 2.2886094086516096e-07 -1.0423630669720296e-07</pose>
				<geometry>
					<mesh>
						<uri>model://google_grasp/meshes/visual/VIS_hollie_028_ringfinger_topsegment_bf_rot_Coll.dae</uri>
						<scale>1.0 0.9999997019767761 0.9999997019767761</scale>
					</mesh>
				</geometry>
			</collision>
			<visual name="VIS_hollhollie_028_ringfinger_topsegment_bf_rot">
				<pose>4.0103938658830884e-07 1.6059398149081971e-06 -2.1079935663692595e-07 -0.027183478698134422 3.4597891840348893e-07 1.3216736078902613e-06</pose>
				<geometry>
					<mesh>
						<uri>model://google_grasp/meshes/visual/VIS_hollhollie_028_ringfinger_topsegment_bf_rot.dae</uri>
						<scale>1.0 0.9999997019767761 0.9999997019767761</scale>
					</mesh>
				</geometry>
			</visual>
		</link>
		<link name="cup_segment">
			<self_collide>true</self_collide>
			<pose>0.25 -0.6600000262260437 0.8200000166893005 0.0420353412628174 0.0235987901687622 -0.017453292384743687</pose>
			<inertial>
				<mass>1000.0</mass>
				<pose>0 0 0 0 0 0</pose>
				<inertia>
					<ixx>1.0</ixx>
					<ixy>0.0</ixy>
					<ixz>0.0</ixz>
					<iyy>1.0</iyy>
					<iyz>0.0</iyz>
					<izz>1.0</izz>
				</inertia>
			</inertial>
			<visual name="VIS_Obj_1_Cup">
				<pose>-0.008555232547223568 0.01832547038793564 0.008990321308374405 0.0691862553358078 -2.6449549198150635 -0.031936366111040115</pose>
				<geometry>
					<mesh>
						<uri>model://google_grasp/meshes/visual/VIS_Obj_1_Cup.dae</uri>
						<scale>0.03999999910593033 0.03999999910593033 0.03999999910593033</scale>
					</mesh>
				</geometry>
			</visual>
			<collision name="COL_Obj_1_Cup">
				<pose>-0.008555232547223568 0.01832547038793564 0.008990321308374405 0.0691862553358078 -2.6449549198150635 -0.031936366111040115</pose>
				<geometry>
					<mesh>
						<uri>model://google_grasp/meshes/visual/VIS_Obj_1_Cup.dae</uri>
						<scale>0.03999999910593033 0.03999999910593033 0.03999999910593033</scale>
					</mesh>
				</geometry>
                                <surface>
                                        <friction>
                                            <ode>
                                                <mu>100</mu>
                                                <mu2>50</mu2>
                                            </ode>
                                        </friction>
                                </surface>
			</collision>
		</link>
		<link name="duck_segment">
			<self_collide>true</self_collide>
			<pose>0.06499999761581421 -0.75 0.8399999523162842 -1.2391838153176984 1.0297442992501937 3.141592653589793</pose>
			<inertial>
				<mass>1000.0</mass>
				<pose>0 0 0 0 0 0</pose>
				<inertia>
					<ixx>1.0</ixx>
					<ixy>0.0</ixy>
					<ixz>0.0</ixz>
					<iyy>1.0</iyy>
					<iyz>0.0</iyz>
					<izz>1.0</izz>
				</inertia>
			</inertial>
			<visual name="VIS_Obj_2_RubberDuck">
				<pose>0.003590993583202362 -0.00020880252122879028 0.0032362081110477448 -0.010118139907717705 -1.7941516637802124 0.06953498721122742</pose>
				<geometry>
					<mesh>
						<uri>model://google_grasp/meshes/visual/VIS_Obj_2_RubberDuck.dae</uri>
						<scale>0.02500000409781933 0.02500000223517418 0.02500000037252903</scale>
					</mesh>
				</geometry>
			</visual>
			<collision name="COL_Obj_2_RubberDuck">
				<pose>0.003590993583202362 -0.00020880252122879028 0.0032362081110477448 -0.010118139907717705 -1.7941516637802124 0.06953498721122742</pose>
				<geometry>
					<mesh>
						<uri>model://google_grasp/meshes/visual/VIS_Obj_2_RubberDuck.dae</uri>
						<scale>0.02500000409781933 0.02500000223517418 0.02500000037252903</scale>
					</mesh>
                                </geometry>
                                <surface>
                                    <friction>
                                        <ode>
                                            <mu>100</mu>
                                            <mu2>50</mu2>
                                        </ode>
                                    </friction>
                                </surface>
			</collision>
		</link>
		<link name="brush_segment">
			<self_collide>true</self_collide>
			<pose>-0.012000000104308128 -0.8799999952316284 0.8599999904632568 1.2915436029434204 0.3665191233158112 0.13962632417678833</pose>
			<inertial>
				<mass>1000.0</mass>
				<pose>0 0 0 0 0 0</pose>
				<inertia>
					<ixx>1.0</ixx>
					<ixy>0.0</ixy>
					<ixz>0.0</ixz>
					<iyy>1.0</iyy>
					<iyz>0.0</iyz>
					<izz>1.0</izz>
				</inertia>
			</inertial>
			<visual name="VIS_Obj_3_Brush">
				<pose>0.006612427532672882 0.0033982726745307446 -0.012920891866087914 0.02386283129453659 -0.5016315579414368 -0.14117811620235443</pose>
				<geometry>
					<mesh>
						<uri>model://google_grasp/meshes/visual/VIS_Obj_3_Brush.dae</uri>
						<scale>0.025000005960464478 0.02500000037252903 0.02500000037252903</scale>
					</mesh>
				</geometry>
			</visual>
			<collision name="COL_Obj_3_Brush">
				<pose>0.006612427532672882 0.0033982726745307446 -0.012920891866087914 0.02386283129453659 -0.5016315579414368 -0.14117811620235443</pose>
				<geometry>
					<mesh>
						<uri>model://google_grasp/meshes/visual/VIS_Obj_3_Brush.dae</uri>
						<scale>0.025000005960464478 0.02500000037252903 0.02500000037252903</scale>
					</mesh>
				</geometry>
			</collision>
		</link>
		<link name="Obj_3">
			<self_collide>true</self_collide>
			<pose>0.11999999731779099 -0.8299999833106995 0.9900000095367432 1.2042771577835083 -0.30368727445602417 0.01745329052209854</pose>
			<inertial>
				<mass>1.0</mass>
				<pose>0 0 0 0 0 0</pose>
				<inertia>
					<ixx>1.0</ixx>
					<ixy>0.0</ixy>
					<ixz>0.0</ixz>
					<iyy>1.0</iyy>
					<iyz>0.0</iyz>
					<izz>1.0</izz>
				</inertia>
			</inertial>
			<collision name="COL_Obj_3_Banana_Coll">
				<pose>-0.18325242400169373 -0.042692892253398895 -0.003859103424474597 2.755162711309822e-07 3.686485428033848e-08 -8.197579859370308e-08</pose>
				<geometry>
					<mesh>
						<uri>model://google_grasp/meshes/collisions/COL_Obj_3_Banana_Coll.dae</uri>
						<scale>0.11999999731779099 0.11999999731779099 0.11999999731779099</scale>
					</mesh>
				</geometry>
			</collision>
			<visual name="VIS_Obj_3_Banana">
				<pose>-0.18325242400169373 -0.042692892253398895 -0.003859103424474597 2.755162711309822e-07 3.686485428033848e-08 -8.197579859370308e-08</pose>
				<geometry>
					<mesh>
						<uri>model://google_grasp/meshes/visual/VIS_Obj_3_Banana.dae</uri>
						<scale>0.11999999731779099 0.11999999731779099 0.11999999731779099</scale>
					</mesh>
				</geometry>
			</visual>
		</link>
		<link name="Obj_4">
			<self_collide>true</self_collide>
			<pose>0.20000000298023224 -0.949999988079071 0.9300000071525574 1.5707963705062866 -0.6806783676147461 -0.9669124484062195</pose>
			<inertial>
				<mass>1.0</mass>
				<pose>0 0 0 0 0 0</pose>
				<inertia>
					<ixx>1.0</ixx>
					<ixy>0.0</ixy>
					<ixz>0.0</ixz>
					<iyy>1.0</iyy>
					<iyz>0.0</iyz>
					<izz>1.0</izz>
				</inertia>
			</inertial>
			<collision name="COL_Obj_4_Can_Coll">
				<pose>-6.83516263961792e-05 -0.003405354917049408 -0.0034073293209075928 4.6566137257286755e-07 3.1044091741705415e-08 -4.6566135836201283e-08</pose>
				<geometry>
					<mesh>
						<uri>model://google_grasp/meshes/collisions/COL_Obj_4_Can_Coll.dae</uri>
						<scale>0.029999999329447746 0.029999999329447746 0.029999997466802597</scale>
					</mesh>
				</geometry>
			</collision>
			<visual name="VIS_Obj_4_Can">
				<pose>-6.83516263961792e-05 -0.003405354917049408 -0.0034073293209075928 4.6566137257286755e-07 3.1044091741705415e-08 -4.6566135836201283e-08</pose>
				<geometry>
					<mesh>
						<uri>model://google_grasp/meshes/visual/VIS_Obj_4_Can.dae</uri>
						<scale>0.029999999329447746 0.029999999329447746 0.029999997466802597</scale>
					</mesh>
				</geometry>
			</visual>
		</link>
		<link name="Obj_5">
			<self_collide>true</self_collide>
			<pose>0.07000000029802322 -0.6200000047683716 1.0 1.0629055500030518 -0.45727628469467163 0.7452555894851685</pose>
			<inertial>
				<mass>1.0</mass>
				<pose>0 0 0 0 0 0</pose>
				<inertia>
					<ixx>1.0</ixx>
					<ixy>0.0</ixy>
					<ixz>0.0</ixz>
					<iyy>1.0</iyy>
					<iyz>0.0</iyz>
					<izz>1.0</izz>
				</inertia>
			</inertial>
			<collision name="COL_Obj_5_Football_Coll">
				<pose>0.00024674832820892334 -0.002815432846546173 -0.00025904737412929535 3.8029008919693297e-07 1.5522044805038604e-07 -4.268562037168522e-08</pose>
				<geometry>
					<mesh>
						<uri>model://google_grasp/meshes/collisions/COL_Obj_5_Football_Coll.dae</uri>
						<scale>0.029999999329447746 0.029999999329447746 0.029999999329447746</scale>
					</mesh>
				</geometry>
			</collision>
			<visual name="VIS_Obj_5_Football">
				<pose>0.00024674832820892334 -0.002815432846546173 -0.00025904737412929535 3.8029008919693297e-07 1.5522044805038604e-07 -4.268562037168522e-08</pose>
				<geometry>
					<mesh>
						<uri>model://google_grasp/meshes/visual/VIS_Obj_5_Football.dae</uri>
						<scale>0.029999999329447746 0.029999999329447746 0.029999999329447746</scale>
					</mesh>
				</geometry>
			</visual>
		</link>
		<link name="Obj_6">
			<self_collide>true</self_collide>
			<pose>0.30000001192092896 -0.7900000214576721 1.0 2.3212878704071045 -0.692895770072937 -0.16231562197208405</pose>
			<inertial>
				<mass>1.0</mass>
				<pose>0 0 0 0 0 0</pose>
				<inertia>
					<ixx>1.0</ixx>
					<ixy>0.0</ixy>
					<ixz>0.0</ixz>
					<iyy>1.0</iyy>
					<iyz>0.0</iyz>
					<izz>1.0</izz>
				</inertia>
			</inertial>
			<collision name="COL_Obj_6_Lightbulb_Coll">
				<pose>0.06560074537992477 0.031300514936447144 0.053160324692726135 -0.008726583793759346 -3.0073960033405456e-07 -2.0372681319713593e-07</pose>
				<geometry>
					<mesh>
						<uri>model://google_grasp/meshes/collisions/COL_Obj_6_Lightbulb_Coll.dae</uri>
						<scale>0.012000000104308128 0.011999999172985554 0.012000000104308128</scale>
					</mesh>
				</geometry>
			</collision>
			<visual name="VIS_Obj_6_Lightbulb">
				<pose>0.06560074537992477 0.031300514936447144 0.053160324692726135 -0.008726583793759346 -3.0073960033405456e-07 -2.0372681319713593e-07</pose>
				<geometry>
					<mesh>
						<uri>model://google_grasp/meshes/visual/VIS_Obj_6_Lightbulb.dae</uri>
						<scale>0.012000000104308128 0.011999999172985554 0.012000000104308128</scale>
					</mesh>
				</geometry>
			</visual>
		</link>
		<link name="Obj_7">
			<self_collide>true</self_collide>
			<pose>-0.027499999850988388 -0.9700000286102295 1.1100000143051147 -0.5253441333770752 -0.2059488594532013 -0.23911009728908542</pose>
			<inertial>
				<mass>1.0</mass>
				<pose>0 0 0 0 0 0</pose>
				<inertia>
					<ixx>1.0</ixx>
					<ixy>0.0</ixy>
					<ixz>0.0</ixz>
					<iyy>1.0</iyy>
					<iyz>0.0</iyz>
					<izz>1.0</izz>
				</inertia>
			</inertial>
			<collision name="COL_Obj_7_Pin_Coll">
				<pose>-0.0018854988738894463 0.11175277829170227 -0.00020171012147329748 9.943810397317066e-08 5.335703434639072e-08 -1.9402557782655094e-08</pose>
				<geometry>
					<mesh>
						<uri>model://google_grasp/meshes/collisions/COL_Obj_7_Pin_Coll.dae</uri>
						<scale>0.011999999172985554 0.012000000104308128 0.012000000104308128</scale>
					</mesh>
				</geometry>
			</collision>
			<visual name="VIS_Obj_7_Pin">
				<pose>-0.0018854988738894463 0.11175277829170227 -0.00020171012147329748 9.943810397317066e-08 5.335703434639072e-08 -1.9402557782655094e-08</pose>
				<geometry>
					<mesh>
						<uri>model://google_grasp/meshes/visual/VIS_Obj_7_Pin.dae</uri>
						<scale>0.011999999172985554 0.012000000104308128 0.012000000104308128</scale>
					</mesh>
				</geometry>
			</visual>
		</link>
		<link name="Obj_8">
			<self_collide>true</self_collide>
			<pose>0.3059999942779541 -0.8659999966621399 0.9649999737739563 2.0071287155151367 -0.36477380990982056 -0.2111848443746567</pose>
			<inertial>
				<mass>1.0</mass>
				<pose>0 0 0 0 0 0</pose>
				<inertia>
					<ixx>1.0</ixx>
					<ixy>0.0</ixy>
					<ixz>0.0</ixz>
					<iyy>1.0</iyy>
					<iyz>0.0</iyz>
					<izz>1.0</izz>
				</inertia>
			</inertial>
			<collision name="COL_Obt_8_Bottle_Coll">
				<pose>0.0009609907865524292 -0.00979699194431305 -0.00017449725419282913 -0.005236026365309954 1.1641533959050321e-08 -2.7939682567534874e-08</pose>
				<geometry>
					<mesh>
						<uri>model://google_grasp/meshes/collisions/COL_Obt_8_Bottle_Coll.dae</uri>
						<scale>0.09999999403953552 0.10000000149011612 0.10000000149011612</scale>
					</mesh>
				</geometry>
			</collision>
			<visual name="VIS_Obt_8_Bottle">
				<pose>0.0009609907865524292 -0.00979699194431305 -0.00017449725419282913 -0.005236026365309954 1.1641533959050321e-08 -2.7939682567534874e-08</pose>
				<geometry>
					<mesh>
						<uri>model://google_grasp/meshes/visual/VIS_Obt_8_Bottle.dae</uri>
						<scale>0.09999999403953552 0.10000000149011612 0.10000000149011612</scale>
					</mesh>
				</geometry>
			</visual>
		</link>
		
		<joint name="arm_0_joint_base_z_rot" type="fixed">
			<parent>base_link</parent>
			<child>arm_0_link_link_base_z_rot</child>
			<axis>
				<xyz>0.0 0.0 1.0</xyz>
				<limit>
					<lower>-1.5707963267948966</lower>
					<upper>1.5707963267948966</upper>
  				        <effort>1000</effort>
       					<velocity>4</velocity>
				</limit>			
				<dynamics>
          				<damping>1</damping>
          				<friction>0</friction>
          				<spring_reference>0</spring_reference>
          				<spring_stiffness>0</spring_stiffness>
        			</dynamics>
			</axis>

		</joint>
		<joint name="hollie_000_joint" type="revolute">
			<parent>arm_0_link_link_base_z_rot</parent>
			<child>hollie_000</child>
			<axis>
				<xyz>0.0 0.0 1.0</xyz>
				<limit>
					<lower>-1.5707963267948966</lower>
					<upper>1.5707963267948966</upper>
  				        <effort>1000</effort>
       					<velocity>4</velocity>
				</limit>
				<dynamics>
          				<damping>1</damping>
          				<friction>0</friction>
          				<spring_reference>0</spring_reference>
          				<spring_stiffness>0</spring_stiffness>
        			</dynamics>
			</axis>
		</joint>
		<joint name="hollie_001_base_x_rot_joint" type="revolute">
			<parent>hollie_000</parent>
			<child>hollie_001_base_x_rot</child>
			<axis>
				<xyz>0.0 0.0 1.0</xyz>
				<limit>
					<lower>-1.5707963267948966</lower>
					<upper>1.5707963267948966</upper>
  				        <effort>1000</effort>
       					<velocity>4</velocity>
				</limit>
				<dynamics>
          				<damping>1</damping>
          				<friction>0</friction>
          				<spring_reference>0</spring_reference>
          				<spring_stiffness>0</spring_stiffness>
        			</dynamics>
			</axis>
		</joint>
		<joint name="hollie_002_upper_x_rot_joint" type="revolute">
			<parent>hollie_001_base_x_rot</parent>
			<child>hollie_002_upper_x_rot</child>
			<axis>
				<xyz>0.0 0.0 1.0</xyz>
				<limit>
					<lower>-2.748893571891069</lower>
					<upper>2.748893571891069</upper>
  				        <effort>1000</effort>
       					<velocity>4</velocity>
				</limit>
				<dynamics>
          				<damping>1</damping>
          				<friction>0</friction>
          				<spring_reference>0</spring_reference>
          				<spring_stiffness>0</spring_stiffness>
        			</dynamics>
			</axis>
		</joint>
		<joint name="hollie_003_joint" type="revolute">
			<parent>hollie_002_upper_x_rot</parent>
			<child>hollie_003</child>
			<axis>
				<xyz>0.0 0.0 1.0</xyz>
				<limit>
					<lower>-1.5707963267948966</lower>
					<upper>1.5707963267948966</upper>
  				        <effort>1000</effort>
       					<velocity>4</velocity>
				</limit>
				<dynamics>
          				<damping>1</damping>
          				<friction>0</friction>
          				<spring_reference>0</spring_reference>
          				<spring_stiffness>0</spring_stiffness>
        			</dynamics>
			</axis>
		</joint>
		<joint name="hollie_004_wrist_x_rot_joint" type="revolute">
			<parent>hollie_003</parent>
			<child>hollie_004_wrist_x_rot</child>
			<axis>
				<xyz>0.0 0.0 1.0</xyz>
				<limit>
					<lower>-2.6179938779914944</lower>
					<upper>2.6179938779914944</upper>
  				        <effort>1000</effort>
       					<velocity>4</velocity>
				</limit>
				<dynamics>
          				<damping>1</damping>
          				<friction>0</friction>
          				<spring_reference>0</spring_reference>
          				<spring_stiffness>0</spring_stiffness>
        			</dynamics>
			</axis>
		</joint>
		<joint name="hollie_005_joint" type="fixed">
			<parent>hollie_004_wrist_x_rot</parent>
			<child>hollie_005</child>
			<axis>
				<xyz>0.0 0.0 1.0</xyz>
				<limit>
					<lower>-1.5707963267948966</lower>
					<upper>1.5707963267948966</upper>
  				        <effort>1000</effort>
       					<velocity>4</velocity>
				</limit>
				<dynamics>
          				<damping>1</damping>
          				<friction>0</friction>
          				<spring_reference>0</spring_reference>
          				<spring_stiffness>0</spring_stiffness>
        			</dynamics>
			</axis>
		</joint>
		<joint name="hollie_006_wrist_lat_rot_joint" type="revolute">
			<parent>hollie_005</parent>
			<child>hollie_006_wrist_lat_rot</child>
			<axis>
				<xyz>0.0 0.0 1.0</xyz>
				<limit>
					<lower>-1.5707963267948966</lower>
					<upper>1.5707963267948966</upper>
  				        <effort>1000</effort>
       					<velocity>4</velocity>
				</limit>
				<dynamics>
          				<damping>1</damping>
          				<friction>0</friction>
          				<spring_reference>0</spring_reference>
          				<spring_stiffness>0</spring_stiffness>
        			</dynamics>
			</axis>
		</joint>
		<joint name="hollie_007_wrist_lat_rot_joint" type="fixed">
			<parent>hollie_006_wrist_lat_rot</parent>
			<child>hollie_007_wrist_lat_rot</child>
			<axis>
				<xyz>0.0 0.0 1.0</xyz>
				<limit>
					<lower>-1.5707963267948966</lower>
					<upper>1.5707963267948966</upper>
  				        <effort>1000</effort>
       					<velocity>4</velocity>
				</limit>
				<dynamics>
          				<damping>1</damping>
          				<friction>0</friction>
          				<spring_reference>0</spring_reference>
          				<spring_stiffness>0</spring_stiffness>
        			</dynamics>
			</axis>
		</joint>
		<joint name="hollie_008_thumb_lat_rot_joint" type="revolute">
			<parent>hollie_007_wrist_lat_rot</parent>
			<child>hollie_008_thumb_lat_rot</child>
			<axis>
				<xyz>0.0 0.0 1.0</xyz>
				<limit>
					<lower>0.0</lower>
					<upper>3.141592653589793</upper>
  				        <effort>1000</effort>
       					<velocity>4</velocity>
				</limit>
				<dynamics>
          				<damping>1</damping>
          				<friction>0</friction>
          				<spring_reference>0</spring_reference>
          				<spring_stiffness>0</spring_stiffness>
        			</dynamics>
			</axis>
		</joint>
		<joint name="hand_Thumb_Helper_link_joint" type="revolute">
			<parent>hollie_008_thumb_lat_rot</parent>
			<child>hand_Thumb_Helper_link</child>
			<axis>
				<xyz>0.0 0.0 1.0</xyz>
				<limit>
					<lower>2.0943951023931953</lower>
					<upper>2.0943951023931953</upper>
  				        <effort>15</effort>
       					<velocity>4</velocity>
				</limit>
				<dynamics>
          				<damping>1</damping>
          				<friction>0</friction>
          				<spring_reference>0</spring_reference>
          				<spring_stiffness>0</spring_stiffness>
        			</dynamics>
			</axis>
		</joint>
		<joint name="hollie_009_thumb_base_rot_joint" type="revolute">
			<parent>hand_Thumb_Helper_link</parent>
			<child>hollie_009_thumb_base_rot</child>
			<axis>
				<xyz>-0.0 -0.0 -1.0</xyz>
				<limit>
					<lower>-5.0</lower>
					<upper>0.9599</upper>
  				        <effort>1000</effort>
       					<velocity>4</velocity>
				</limit>
				<dynamics>
          				<damping>1</damping>
          				<friction>0</friction>
          				<spring_reference>0</spring_reference>
          				<spring_stiffness>0</spring_stiffness>
        			</dynamics>
			</axis>
		</joint>
		<joint name="hollie_010_thumb_tip_rot_joint" type="revolute">
			<parent>hollie_009_thumb_base_rot</parent>
			<child>hollie_010_thumb_tip_rot</child>
			<axis>
				<xyz>-0.0 -0.0 -1.0</xyz>
				<limit>
					<lower>-5</lower>
					<upper>0</upper>
  				        <effort>1000</effort>
       					<velocity>4</velocity>
				</limit>
				<dynamics>
          				<damping>1</damping>
          				<friction>0</friction>
          				<spring_reference>0</spring_reference>
          				<spring_stiffness>0</spring_stiffness>
        			</dynamics>
			</axis>
		</joint>
		<joint name="hollie_011_thumb_topsegment_bf_rot_joint" type="revolute">
			<parent>hollie_010_thumb_tip_rot</parent>
			<child>hollie_011_thumb_topsegment_bf_rot</child>
			<axis>
				<xyz>-0.0 -0.0 -1.0</xyz>
				<limit>
					<lower>-5</lower>
					<upper>0.1</upper>
  				        <effort>1000</effort>
       					<velocity>4</velocity>
				</limit>
				<dynamics>
          				<damping>1</damping>
          				<friction>0</friction>
          				<spring_reference>0</spring_reference>
          				<spring_stiffness>0</spring_stiffness>
        			</dynamics>
			</axis>
		</joint>
		<joint name="hand_f1_joint" type="fixed">
			<parent>hollie_007_wrist_lat_rot</parent>
			<child>hand_f1_link</child>
			<axis>
				<xyz>0.0 0.0 1.0</xyz>
				<limit>
					<lower>-1.5707963267948966</lower>
					<upper>1.5707963267948966</upper>
  				        <effort>1000</effort>
       					<velocity>4</velocity>
				</limit>
				<dynamics>
          				<damping>1</damping>
          				<friction>0</friction>
          				<spring_reference>0</spring_reference>
          				<spring_stiffness>0</spring_stiffness>
        			</dynamics>
			</axis>
		</joint>
		<joint name="hand_f2_joint" type="fixed">
			<parent>hand_f1_link</parent>
			<child>hand_f2_link</child>
			<axis>
				<xyz>0.0 0.0 1.0</xyz>
				<limit>
					<lower>0.0</lower>
					<upper>0.0</upper>
  				        <effort>1000</effort>
       					<velocity>4</velocity>
				</limit>				
				<dynamics>
          				<damping>1</damping>
          				<friction>0</friction>
          				<spring_reference>0</spring_reference>
          				<spring_stiffness>0</spring_stiffness>
        			</dynamics>
			</axis>
		</joint>
		<joint name="hand_f3_joint" type="fixed">
			<parent>hand_f2_link</parent>
			<child>hand_f3_link</child>
			<axis>
				<xyz>0.0 0.0 1.0</xyz>
				<limit>
					<lower>0.0</lower>
					<upper>0.0</upper>
  				        <effort>1000</effort>
       					<velocity>4</velocity>
				</limit>
				<dynamics>
          				<damping>1</damping>
          				<friction>0</friction>
          				<spring_reference>0</spring_reference>
          				<spring_stiffness>0</spring_stiffness>
        			</dynamics>
			</axis>
		</joint>
		<joint name="hollie_012_indexfing_lr_rot_joint" type="revolute">
			<parent>hand_f3_link</parent>
			<child>hollie_012_indexfing_lr_rot</child>
			<axis>
				<xyz>0.0 0.0 1.0</xyz>
				<limit>
					<lower>0.0</lower>
					<upper>0.2883299983156006</upper>
  				        <effort>1000</effort>
       					<velocity>4</velocity>
				</limit>
				<dynamics>
          				<damping>1</damping>
          				<friction>0</friction>
          				<spring_reference>0</spring_reference>
          				<spring_stiffness>0</spring_stiffness>
        			</dynamics>
			</axis>
		</joint>
		<joint name="hollie_013_indexfing_bf_rot_joint" type="revolute">
			<parent>hollie_012_indexfing_lr_rot</parent>
			<child>hollie_013_indexfing_bf_rot</child>
			<axis>
				<xyz>0.0 0.0 1.0</xyz>
				<limit>
					<lower>0.0</lower>
					<upper>0.24434609527920614</upper>
  				        <effort>1000</effort>
       					<velocity>4</velocity>
				</limit>
				<dynamics>
          				<damping>1</damping>
          				<friction>0</friction>
          				<spring_reference>0</spring_reference>
          				<spring_stiffness>0</spring_stiffness>
        			</dynamics>
			</axis>
		</joint>
		<joint name="hollie_014_indexfing_midsegment_bf_rot_joint" type="revolute">
			<parent>hollie_013_indexfing_bf_rot</parent>
			<child>hollie_014_indexfing_midsegment_bf_rot</child>
			<axis>
				<xyz>0.0 0.0 1.0</xyz>
				<limit>
					<lower>0.0</lower>
					<upper>1.3264502315156905</upper>
  				        <effort>1000</effort>
       					<velocity>4</velocity>
				</limit>
				<dynamics>
          				<damping>1</damping>
          				<friction>0</friction>
          				<spring_reference>0</spring_reference>
          				<spring_stiffness>0</spring_stiffness>
        			</dynamics>
			</axis>
		</joint>
		<joint name="hollie_015_indexfing_topsegment_bf_rot_joint" type="revolute">
			<parent>hollie_014_indexfing_midsegment_bf_rot</parent>
			<child>hollie_015_indexfing_topsegment_bf_rot</child>
			<axis>
				<xyz>0.0 0.0 1.0</xyz>
				<limit>
					<lower>0.0</lower>
					<upper>1.3962634015954636</upper>
  				        <effort>1000</effort>
       					<velocity>4</velocity>
				</limit>
				<dynamics>
          				<damping>1</damping>
          				<friction>0</friction>
          				<spring_reference>0</spring_reference>
          				<spring_stiffness>0</spring_stiffness>
        			</dynamics>
			</axis>
		</joint>
		<joint name="hollie_016_midfing_lr_rot_joint" type="revolute">
			<parent>hand_f1_link</parent>
			<child>hollie_016_midfing_lr_rot</child>
			<axis>
				<xyz>0.0 0.0 1.0</xyz>
				<limit>
					<lower>-1.5707963267948966</lower>
					<upper>1.5707963267948966</upper>
  				        <effort>1000</effort>
       					<velocity>4</velocity>
				</limit>
				<dynamics>
          				<damping>1</damping>
          				<friction>0</friction>
          				<spring_reference>0</spring_reference>
          				<spring_stiffness>0</spring_stiffness>
        			</dynamics>
			</axis>
		</joint>
		<joint name="hollie_017_midfing_bf_rot_joint" type="revolute">
			<parent>hollie_016_midfing_lr_rot</parent>
			<child>hollie_017_midfing_bf_rot</child>
			<axis>
				<xyz>0.0 0.0 1.0</xyz>
				<limit>
					<lower>0.0</lower>
					<upper>0.24434609527920614</upper>
  				        <effort>1000</effort>
       					<velocity>4</velocity>
				</limit>
				<dynamics>
          				<damping>1</damping>
          				<friction>0</friction>
          				<spring_reference>0</spring_reference>
          				<spring_stiffness>0</spring_stiffness>
        			</dynamics>
			</axis>
		</joint>
		<joint name="hollie_018_midfing_midsegment_bf_rot_joint" type="revolute">
			<parent>hollie_017_midfing_bf_rot</parent>
			<child>hollie_018_midfing_midsegment_bf_rot</child>
			<axis>
				<xyz>0.0 0.0 1.0</xyz>
				<limit>
					<lower>0.0</lower>
					<upper>1.3264502315156905</upper>
  				        <effort>1000</effort>
       					<velocity>4</velocity>
				</limit>
				<dynamics>
          				<damping>1</damping>
          				<friction>0</friction>
          				<spring_reference>0</spring_reference>
          				<spring_stiffness>0</spring_stiffness>
        			</dynamics>
			</axis>
		</joint>
		<joint name="hollie_019_midfing_topsegment_bf_rot_joint" type="revolute">
			<parent>hollie_018_midfing_midsegment_bf_rot</parent>
			<child>hollie_019_midfing_topsegment_bf_rot</child>
			<axis>
				<xyz>0.0 0.0 1.0</xyz>
				<limit>
					<lower>0.0</lower>
					<upper>1.3962634015954636</upper>
  				        <effort>1000</effort>
       					<velocity>4</velocity>
				</limit>
				<dynamics>
          				<damping>1</damping>
          				<friction>0</friction>
          				<spring_reference>0</spring_reference>
          				<spring_stiffness>0</spring_stiffness>
        			</dynamics>
			</axis>
		</joint>
		<joint name="hollie_020_outerhand_rot_joint" type="revolute">
			<parent>hollie_007_wrist_lat_rot</parent>
			<child>hollie_020_outerhand_rot</child>
			<axis>
				<xyz>0.0 0.0 1.0</xyz>
				<limit>
					<lower>-0.5235987755982988</lower>
					<upper>0.0</upper>
  				        <effort>1000</effort>
       					<velocity>4</velocity>
				</limit>
				<dynamics>
          				<damping>1</damping>
          				<friction>0</friction>
          				<spring_reference>0</spring_reference>
          				<spring_stiffness>0</spring_stiffness>
        			</dynamics>
			</axis>
		</joint>
		<joint name="hand_f5_link_joint" type="fixed">
			<parent>hollie_020_outerhand_rot</parent>
			<child>hand_f5_link</child>
			<axis>
				<xyz>0.0 0.0 1.0</xyz>
				<limit>
					<lower>0.0</lower>
					<upper>0.0</upper>
  				        <effort>1000</effort>
       					<velocity>4</velocity>
				</limit>
				<dynamics>
          				<damping>1</damping>
          				<friction>0</friction>
          				<spring_reference>0</spring_reference>
          				<spring_stiffness>0</spring_stiffness>
        			</dynamics>
			</axis>
		</joint>
		<joint name="hand_f6_link_joint" type="fixed">
			<parent>hand_f5_link</parent>
			<child>hand_f6_link</child>
			<axis>
				<xyz>0.0 0.0 1.0</xyz>
				<limit>
					<lower>0.0</lower>
					<upper>0.0</upper>
  				        <effort>1000</effort>
       					<velocity>4</velocity>
				</limit>
				<dynamics>
          				<damping>1</damping>
          				<friction>0</friction>
          				<spring_reference>0</spring_reference>
          				<spring_stiffness>0</spring_stiffness>
        			</dynamics>
			</axis>
		</joint>
		<joint name="hand_f7_link_joint" type="fixed">
			<parent>hand_f6_link</parent>
			<child>hand_f7_link</child>
			<axis>
				<xyz>0.0 0.0 1.0</xyz>
				<limit>
					<lower>-1.5707963267948966</lower>
					<upper>1.5707963267948966</upper>
  				        <effort>1000</effort>
       					<velocity>4</velocity>
				</limit>
				<dynamics>
          				<damping>1</damping>
          				<friction>0</friction>
          				<spring_reference>0</spring_reference>
          				<spring_stiffness>0</spring_stiffness>
        			</dynamics>
			</axis>
		</joint>
		<joint name="hollie_021_littlefinger_lr_rot_joint" type="revolute">
			<parent>hand_f7_link</parent>
			<child>hollie_021_littlefinger_lr_rot</child>
			<axis>
				<xyz>0.0 0.0 1.0</xyz>
				<limit>
					<lower>0.0</lower>
					<upper>0.5828999828023386</upper>
  				        <effort>1000</effort>
       					<velocity>4</velocity>
				</limit>
				<dynamics>
          				<damping>1</damping>
          				<friction>0</friction>
          				<spring_reference>0</spring_reference>
          				<spring_stiffness>0</spring_stiffness>
        			</dynamics>
			</axis>
		</joint>
		<joint name="hollie_022_littlefinger_bf_rot_joint" type="revolute">
			<parent>hollie_021_littlefinger_lr_rot</parent>
			<child>hollie_022_littlefinger_bf_rot</child>
			<axis>
				<xyz>0.0 0.0 1.0</xyz>
				<limit>
					<lower>0.0</lower>
					<upper>0.24434609527920614</upper>
  				        <effort>1000</effort>
       					<velocity>4</velocity>
				</limit>
				<dynamics>
          				<damping>1</damping>
          				<friction>0</friction>
          				<spring_reference>0</spring_reference>
          				<spring_stiffness>0</spring_stiffness>
        			</dynamics>
			</axis>
		</joint>
		<joint name="hollie_023_littlefinger_midsegment_bf_rot_joint" type="revolute">
			<parent>hollie_022_littlefinger_bf_rot</parent>
			<child>hollie_023_littlefinger_midsegment_bf_rot</child>
			<axis>
				<xyz>0.0 0.0 1.0</xyz>
				<limit>
					<lower>0.0</lower>
					<upper>1.3264502315156905</upper>
  				        <effort>1000</effort>
       					<velocity>4</velocity>
				</limit>
				<dynamics>
          				<damping>1</damping>
          				<friction>0</friction>
          				<spring_reference>0</spring_reference>
          				<spring_stiffness>0</spring_stiffness>
        			</dynamics>
			</axis>
		</joint>
		<joint name="hollie_024_littlefinger_topsegment_bf_rot_joint" type="revolute">
			<parent>hollie_023_littlefinger_midsegment_bf_rot</parent>
			<child>hollie_024_littlefinger_topsegment_bf_rot</child>
			<axis>
				<xyz>0.0 0.0 1.0</xyz>
				<limit>
					<lower>0.0</lower>
					<upper>1.3962634015954636</upper>
  				        <effort>1000</effort>
       					<velocity>4</velocity>
				</limit>
				<dynamics>
          				<damping>1</damping>
          				<friction>0</friction>
          				<spring_reference>0</spring_reference>
          				<spring_stiffness>0</spring_stiffness>
        			</dynamics>
			</axis>
		</joint>
		<joint name="hand_f8_joint" type="fixed">
			<parent>hand_f6_link</parent>
			<child>hand_f8_link</child>
			<axis>
				<xyz>0.0 0.0 1.0</xyz>
				<limit>
					<lower>-1.5707963267948966</lower>
					<upper>1.5707963267948966</upper>
  				        <effort>1000</effort>
       					<velocity>4</velocity>
				</limit>
				<dynamics>
          				<damping>1</damping>
          				<friction>0</friction>
          				<spring_reference>0</spring_reference>
          				<spring_stiffness>0</spring_stiffness>
        			</dynamics>
			</axis>
		</joint>
		<joint name="hollie_025_ringfinger_lr_rot_joint" type="revolute">
			<parent>hand_f8_link</parent>
			<child>hollie_025_ringfinger_lr_rot</child>
			<axis>
				<xyz>0.0 0.0 1.0</xyz>
				<limit>
					<lower>0.0</lower>
					<upper>0.2883299983156006</upper>
  				        <effort>1000</effort>
       					<velocity>4</velocity>
				</limit>
				<dynamics>
          				<damping>1</damping>
          				<friction>0</friction>
          				<spring_reference>0</spring_reference>
          				<spring_stiffness>0</spring_stiffness>
        			</dynamics>
			</axis>
		</joint>
		<joint name="hollie_026_ringfinger_bf_rot_joint" type="revolute">
			<parent>hollie_025_ringfinger_lr_rot</parent>
			<child>hollie_026_ringfinger_bf_rot</child>
			<axis>
				<xyz>0.0 0.0 1.0</xyz>
				<limit>
					<lower>0.0</lower>
					<upper>0.9817499679337369</upper>
  				        <effort>1000</effort>
       					<velocity>4</velocity>
				</limit>
				<dynamics>
          				<damping>1</damping>
          				<friction>0</friction>
          				<spring_reference>0</spring_reference>
          				<spring_stiffness>0</spring_stiffness>
        			</dynamics>
			</axis>
		</joint>
		<joint name="hollie_027_ringfinger_midsegment_bf_rot_joint" type="revolute">
			<parent>hollie_026_ringfinger_bf_rot</parent>
			<child>hollie_027_ringfinger_midsegment_bf_rot</child>
			<axis>
				<xyz>0.0 0.0 1.0</xyz>
				<limit>
					<lower>0.0</lower>
					<upper>1.3340000268899561</upper>
  				        <effort>1000</effort>
       					<velocity>4</velocity>
				</limit>
				<dynamics>
          				<damping>1</damping>
          				<friction>0</friction>
          				<spring_reference>0</spring_reference>
          				<spring_stiffness>0</spring_stiffness>
        			</dynamics>
			</axis>
		</joint>
		<joint name="hollie_028_ringfinger_topsegment_bf_rot_joint" type="revolute">
			<parent>hollie_027_ringfinger_midsegment_bf_rot</parent>
			<child>hollie_028_ringfinger_topsegment_bf_rot</child>
			<axis>
				<xyz>0.0 0.0 1.0</xyz>
				<limit>
					<lower>0.0</lower>
					<upper>1.39499999797433</upper>
  				        <effort>1000</effort>
       					<velocity>4</velocity>
				</limit>
				<dynamics>
          				<damping>1</damping>
          				<friction>0</friction>
          				<spring_reference>0</spring_reference>
          				<spring_stiffness>0</spring_stiffness>
        			</dynamics>
			</axis>
		</joint>

    
<!--    PID controller	-->
    <static>0</static>
    <plugin name="grasp_schunk" filename="libgeneric_controller_plugin.so" >

 <!--   <controller joint_name="arm_0_joint_base_z_rot">
        <type>position</type>
	<pid>500.0 10.0 50.0</pid>
    </controller>
-->

    <controller joint_name="hollie_000_joint">
        <type>position</type>
	<pid>500.0 10.0 50.0</pid>
    </controller>
  
    <controller joint_name="hollie_001_base_x_rot_joint">
        <type>position</type>
	<pid>500.0 10.0 50.0</pid>
    </controller>

    <controller joint_name="hollie_002_upper_x_rot_joint">
        <type>position</type>
	<pid>500.0 10.0 50.0</pid>
    </controller>

    <controller joint_name="hollie_003_joint">
        <type>position</type>
	<pid>500.0 10.0 50.0</pid>
    </controller>

     <controller joint_name="hollie_004_wrist_x_rot_joint">
        <type>position</type>
	<pid>500.0 10.0 50.0</pid>
    </controller>


    <controller joint_name="hollie_005_joint">
        <type>position</type>
	<pid>500.0 10.0 50.0</pid>
    </controller>


     <controller joint_name="hand_f1_joint">
        <type>position</type>
	<pid>100.0 0.1 0.1</pid>
    </controller>

     <controller joint_name="hand_f2_joint">
        <type>position</type>
	<pid>100.0 0.1 0.1</pid>
    </controller>

     <controller joint_name="hand_f3_joint">
        <type>position</type>
	<pid>100.0 0.1 0.1</pid>
    </controller>

     <controller joint_name="hand_f5_link_joint">
        <type>position</type>
	<pid>100.0 0.1 0.1</pid>
    </controller>

     <controller joint_name="hand_f6_link_joint">
        <type>position</type>
	<pid>100.0 0.1 0.1</pid>
    </controller>

     <controller joint_name="hand_f8_joint">
        <type>position</type>
	<pid>100.0 0.1 0.1</pid>
    </controller>
  
    <controller joint_name="hollie_006_wrist_lat_rot_joint">
        <type>position</type>
	<pid>100.0 0.1 0.1</pid>
    </controller>

     <controller joint_name="hollie_007_wrist_lat_rot_joint">
        <type>position</type>
	<pid>100.0 0.1 0.1</pid>
    </controller>

    <controller joint_name="hollie_008_thumb_lat_rot_joint">
        <type>position</type>
	<pid>100.0 0.1 0.1</pid>
    </controller>
  
    <controller joint_name="hand_Thumb_Helper_link_joint">
        <type>position</type>
	<pid>100.0 0.1 0.1</pid>
    </controller>

     <controller joint_name="hollie_009_thumb_base_rot_joint">
        <type>position</type>
	<pid>100.0 0.1 0.1</pid>
    </controller>

    <controller joint_name="hollie_010_thumb_tip_rot_joint">
        <type>position</type>
	<pid>100.0 0.1 0.1</pid>
    </controller>
  
    <controller joint_name="hollie_011_thumb_topsegment_bf_rot_joint">
        <type>position</type>
	<pid>100.0 0.1 0.1</pid>
    </controller>

     <controller joint_name="hollie_012_indexfing_lr_rot_joint">
        <type>position</type>
	<pid>100.0 0.1 0.1</pid>
    </controller>

     <controller joint_name="hollie_013_indexfing_bf_rot_joint">
        <type>position</type>
	<pid>100.0 0.1 0.1</pid>
    </controller>

     <controller joint_name="hollie_014_indexfing_midsegment_bf_rot_joint">
        <type>position</type>
	<pid>100.0 0.1 0.1</pid>
    </controller>

     <controller joint_name="hollie_015_indexfing_topsegment_bf_rot_joint">
        <type>position</type>
	<pid>100.0 0.1 0.1</pid>
    </controller>

     <controller joint_name="hollie_016_midfing_lr_rot_joint">
        <type>position</type>
	<pid>100.0 0.1 0.1</pid>
    </controller>

     <controller joint_name="hollie_017_midfing_bf_rot_joint">
        <type>position</type>
	<pid>100.0 0.1 0.1</pid>
    </controller>

     <controller joint_name="hollie_018_midfing_midsegment_bf_rot_joint">
        <type>position</type>
	<pid>100.0 0.1 0.1</pid>
    </controller>

     <controller joint_name="hollie_019_midfing_topsegment_bf_rot_joint">
        <type>position</type>
	<pid>100.0 0.1 0.1</pid>
    </controller>

     <controller joint_name="hollie_021_littlefinger_lr_rot_joint">
        <type>position</type>
	<pid>100.0 0.1 0.1</pid>
    </controller>

     <controller joint_name="hollie_022_littlefinger_bf_rot_joint">
        <type>position</type>
	<pid>100.0 0.1 0.1</pid>
    </controller>

     <controller joint_name="hollie_023_littlefinger_midsegment_bf_rot_joint">
        <type>position</type>
	<pid>100.0 0.1 0.1</pid>
    </controller>

     <controller joint_name="hollie_024_littlefinger_topsegment_bf_rot_joint">
        <type>position</type>
	<pid>100.0 0.1 0.1</pid>
    </controller>

     <controller joint_name="hollie_025_ringfinger_lr_rot_joint">
        <type>position</type>
	<pid>100.0 0.1 0.1</pid>
    </controller>

     <controller joint_name="hollie_026_ringfinger_bf_rot_joint">
        <type>position</type>
	<pid>100.0 0.1 0.1</pid>
    </controller>

     <controller joint_name="hollie_027_ringfinger_midsegment_bf_rot_joint">
        <type>position</type>
	<pid>100.0 0.1 0.1</pid>
    </controller>

     <controller joint_name="hollie_028_ringfinger_topsegment_bf_rot_joint">
        <type>position</type>
	<pid>100.0 0.1 0.1</pid>
    </controller>

     <controller joint_name="hollie_020_outerhand_rot_joint">
        <type>position</type>
	<pid>100.0 0.1 0.1</pid>
    </controller>

    </plugin>

<!--
   <plugin name="gazebo_grasp_fix" filename="libgazebo_grasp_fix.so">
        <arm>
           <arm_name>robot</arm_name>
           <palm_link>hollie_007_wrist_lat_rot</palm_link>
           <gripper_link>hollie_011_thumb_topsegment_bf_rot</gripper_link>
           <!-index finger-
           <gripper_link>hollie_015_indexfing_topsegment_bf_rot</gripper_link>
           <!-middle finger-
           <gripper_link>hollie_019_midfing_topsegment_bf_rot</gripper_link>
           <!-pinky finger-
           <gripper_link>hollie_024_littlefinger_topsegment_bf_rot</gripper_link>
           <!-ring finger-
           <gripper_link>hollie_028_ringfinger_topsegment_bf_rot</gripper_link>
        </arm>
       <forces_angle_tolerance>100</forces_angle_tolerance>
       <update_rate>4</update_rate>
       <grip_count_threshold>4</grip_count_threshold>
       <max_grip_count>8</max_grip_count>
       <release_tolerance>0.005</release_tolerance>
       <disable_collisions_on_attach>false</disable_collisions_on_attach>
       <contact_topic>__default_topic__</contact_topic>
    </plugin>
-->
</model>
</sdf>

