<?xml version="1.0" ?>
<sdf version="1.5">
	<model name="google_grasp">
		<link name="base_link">
			<pose>0.0 0.0 0.0 0.0 -0.0 0.0</pose>
			<inertial>
				<mass>100.0</mass>
				<pose>0.0 0.0 0.0 0.0 -0.0 0.0</pose>
				<inertia>
					<ixx>100.0</ixx>
					<ixy>0.0</ixy>
					<ixz>1.0</ixz>
					<iyy>100.0</iyy>
					<iyz>1.0</iyz>
					<izz>100.0</izz>
				</inertia>
			</inertial>
			<collision name="VIS_Camera_Fixture_Coll_2">
				<pose>0.28347 -0.33897 1.455229 0.0 -0.0 0.0</pose>
				<geometry>
					<mesh>
						<uri>model://google_grasp/meshes/visual/VIS_Camera_Fixture_Coll_2.dae</uri>
						<scale>0.04 0.04 0.45</scale>
					</mesh>
				</geometry>
			</collision>
			<collision name="VIS_base_link_table_1">
				<pose>-0.02010 -0.29250 0.38800 0.0 -0.0 0.0</pose>
				<geometry>
					<mesh>
						<uri>model://google_grasp/meshes/visual/VIS_base_link_table_1.dae</uri>
						<scale>0.44 0.90 0.39</scale>
					</mesh>
				</geometry>
			</collision>
			<collision name="VIS_Bins_12_Coll">
				<pose>-0.02002 -0.87279 0.71200 1.57080 -0.0 0.0</pose>
				<geometry>
					<mesh>
						<uri>model://google_grasp/meshes/visual/VIS_Bins_12_Coll.dae</uri>
						<scale>0.01 0.011 0.01</scale>
					</mesh>
				</geometry>
			</collision>
			<visual name="VIS_Camera_9_4">
				<pose>0.32804 -0.43959 1.63634 -1.15192 5.08527e-15 -3.1416</pose>
				<geometry>
					<mesh>
						<uri>model://google_grasp/meshes/visual/VIS_Camera_9_4.dae</uri>
						<scale>0.01 0.01 0.01</scale>
					</mesh>
				</geometry>
			</visual>
			<visual name="VIS_Camera_Fixture_10_3">
				<pose>0.26528 -0.33789 1.11712 1.570796 -0.0 0.0</pose>
				<geometry>
					<mesh>
						<uri>model://google_grasp/meshes/visual/VIS_Camera_Fixture_10_3.dae</uri>
						<scale>0.007 0.009 0.007</scale>
					</mesh>
				</geometry>
			</visual>
			<visual name="VIS_Table_11_2">
				<pose>-0.02002 -0.87278 0.71271 1.57079 -0.0 0.0</pose>
				<geometry>
					<mesh>
						<uri>model://google_grasp/meshes/visual/VIS_Table_11_2.dae</uri>
						<scale>0.008 0.011 0.008</scale>
					</mesh>
				</geometry>
			</visual>
			<visual name="VIS_Bins_12">
				<pose>-0.02000 -0.87279 0.71200 1.570796 -0.0 0.0</pose>
				<geometry>
					<mesh>
						<uri>model://google_grasp/meshes/visual/VIS_Bins_12_Coll.dae</uri>
						<scale>0.008 0.011 0.008</scale>
					</mesh>
				</geometry>
			</visual>
			<visual name="VIS_base_link_13">
				<pose>0.0 0.0 0.5 0.0 -0.0 0.0</pose>
				<geometry>
					<mesh>
						<uri>model://google_grasp/meshes/visual/VIS_base_link_13.dae</uri>
						<scale>1.0 1.0 1.0</scale>
					</mesh>
				</geometry>
			</visual>

			<sensor type="camera" name="camera_eye">
        			<pose>0.32 -0.44 1.65 3.14 2.0 1.24</pose>
        			<update_rate>30.0</update_rate>
        			<always_on>1</always_on>
        			<visualize>true</visualize>
        			<topic>/grasping_camera/image</topic>
        			<camera name="camera_eye">
          				<horizontal_fov>0.9</horizontal_fov>
          				<image>
            					<width>320</width>
            					<height>240</height>
            					<format>R8G8B8</format>
          				</image>
          				<clip>
            					<near>0.01</near>
            					<far>100</far>
          				</clip>
					<!--
          				<noise>
            					<type>gaussian</type>-->
            					<!-- Noise is sampled independently per pixel on each frame.
                 				That pixel's noise value is added to each of its color
                 				channels, which at that point lie in the range [0,1]. -->
						<!--            <mean>0.0</mean>
            					<stddev>0.007</stddev>
          				</noise>
					-->
        			</camera>
       				<plugin name="camera_controller" filename="libgazebo_ros_camera.so">
      					<alwaysOn>true</alwaysOn>
          				<updateRate>30.0</updateRate>
          				<cameraName>camera_eye</cameraName>
          				<imageTopicName>image_raw</imageTopicName>
          				<cameraInfoTopicName>camera_info</cameraInfoTopicName>
          				<frameName>camera_link</frameName>
          				<hackBaseline>0.07</hackBaseline>
          				<distortionK1>0.0</distortionK1>
         				<distortionK2>0.0</distortionK2>
          				<distortionK3>0.0</distortionK3>
          				<distortionT1>0.0</distortionT1>
          				<distortionT2>0.0</distortionT2>
        			</plugin>
      			</sensor>
		</link>

<!-- bin objects -->
		<link name="Obj_1">
			<self_collide>true</self_collide>
			<pose>0.25 -0.6800000071525574 0.9399999976158142 0.972148358821869 -0.27750730514526367 -2.687807083129883</pose>
			<inertial>
				<mass>11.517146110534668</mass>
				<pose>0 0 0 0 0 0</pose>
				<inertia>
					<ixx>0.077557806968688965</ixx>
					<ixy>0.0</ixy>
					<ixz>0.0</ixz>
					<iyy>0.11491321563720703</iyy>
					<iyz>0.0</iyz>
					<izz>0.11905232429504395</izz>
				</inertia>
			</inertial>
			<collision name="COL_Obj_1_Cup_Coll">
				<pose>-0.0016019493341445923 -0.006277792155742645 0.0005716346204280853 0.00035536944051273167 0.0007357565336860716 0.00017565912276040763</pose>
				<geometry>
					<mesh>
						<uri>model://google_grasp/meshes/collisions/COL_Obj_1_Cup_Coll.dae</uri>
						<scale>0.03999999910593033 0.03999999910593033 0.03999999910593033</scale>
					</mesh>
				</geometry>
			</collision>
			<visual name="VIS_Obj_1_Cup">
				<pose>-0.0016019493341445923 -0.006277792155742645 0.0005716346204280853 0.00035536944051273167 0.0007357565336860716 0.00017565912276040763</pose>
				<geometry>
					<mesh>
						<uri>model://google_grasp/meshes/visual/VIS_Obj_1_Cup.dae</uri>
						<scale>0.03999999910593033 0.03999999910593033 0.03999999910593033</scale>
					</mesh>
				</geometry>
			</visual>
		</link>
		<link name="Obj_2">
			<self_collide>true</self_collide>
			<pose>0.07000000029802322 -0.8549999952316284 1.0499999523162842 -0.48520153760910034 -0.36826443672180176 -1.7627825736999512</pose>
			<inertial>
				<mass>29.855024337768555</mass>
				<pose>0 0 0 0 0 0</pose>
				<inertia>
					<ixx>0.06012697982788086</ixx>
					<ixy>0.0</ixy>
					<ixz>0.0</ixz>
					<iyy>0.04362722396850586</iyy>
					<iyz>0.0</iyz>
					<izz>0.046967262268066406</izz>
				</inertia>
			</inertial>
			<collision name="COL_Obj_2_RubberDuck_Coll">
				<pose>-0.0013048071414232254 -0.006235934793949127 -0.0056676678359508514 0.003324404824525118 -0.0038171657361090183 0.0062555852346122265</pose>
				<geometry>
					<mesh>
						<uri>model://google_grasp/meshes/collisions/COL_Obj_2_RubberDuck_Coll.dae</uri>
						<scale>0.02500000409781933 0.02500000223517418 0.02500000037252903</scale>
					</mesh>
				</geometry>
			</collision>
			<visual name="VIS_Obj_2_RubberDuck">
				<pose>-0.0013048071414232254 -0.006235934793949127 -0.0056676678359508514 0.003324404824525118 -0.0038171657361090183 0.0062555852346122265</pose>
				<geometry>
					<mesh>
						<uri>model://google_grasp/meshes/visual/VIS_Obj_2_RubberDuck.dae</uri>
						<scale>0.02500000409781933 0.02500000223517418 0.02500000037252903</scale>
					</mesh>
				</geometry>
			</visual>
		</link>
		<link name="Obj_3">
			<self_collide>true</self_collide>
			<pose>0.11999999731779099 -0.8299999833106995 0.9900000095367432 1.2042771577835083 -0.30368727445602417 0.01745329052209854</pose>
			<inertial>
				<mass>0.8622732758522034</mass>
				<pose>0 0 0 0 0 0</pose>
				<inertia>
					<ixx>0.010104811936616898</ixx>
					<ixy>0.0</ixy>
					<ixz>0.0</ixz>
					<iyy>0.02979417145252228</iyy>
					<iyz>0.0</iyz>
					<izz>0.022718265652656555</izz>
				</inertia>
			</inertial>
			<collision name="COL_Obj_3_Banana_Coll">
				<pose>-0.18325242400169373 -0.042692892253398895 -0.003859103424474597 2.755162711309822e-07 3.686485428033848e-08 -8.197579859370308e-08</pose>
				<geometry>
					<mesh>
						<uri>model://google_grasp/meshes/collisions/COL_Obj_3_Banana_Coll.dae</uri>
						<scale>0.11999999731779099 0.11999999731779099 0.11999999731779099</scale>
					</mesh>
				</geometry>
			</collision>
			<visual name="VIS_Obj_3_Banana">
				<pose>-0.18325242400169373 -0.042692892253398895 -0.003859103424474597 2.755162711309822e-07 3.686485428033848e-08 -8.197579859370308e-08</pose>
				<geometry>
					<mesh>
						<uri>model://banana/meshes/visual/VIS_Obj_3_Banana.dae</uri>
						<scale>0.11999999731779099 0.11999999731779099 0.11999999731779099</scale>
					</mesh>
				</geometry>
			</visual>
		</link>
		<link name="Obj_4">
			<self_collide>true</self_collide>
			<pose>0.20000000298023224 -0.949999988079071 0.9300000071525574 1.5707963705062866 -0.6806783676147461 -0.9669124484062195</pose>
			<inertial>
				<mass>17.113351821899414</mass>
				<pose>0 0 0 0 0 0</pose>
				<inertia>
					<ixx>0.02040497589111328</ixx>
					<ixy>0.0</ixy>
					<ixz>0.0</ixz>
					<iyy>0.016866682052612305</iyy>
					<iyz>0.0</iyz>
					<izz>0.020349002838134766</izz>
				</inertia>
			</inertial>
			<collision name="COL_Obj_4_Can_Coll">
				<pose>-6.83516263961792e-05 -0.003405354917049408 -0.0034073293209075928 4.6566137257286755e-07 3.1044091741705415e-08 -4.6566135836201283e-08</pose>
				<geometry>
					<mesh>
						<uri>model://google_grasp/meshes/collisions/COL_Obj_4_Can_Coll.dae</uri>
						<scale>0.029999999329447746 0.029999999329447746 0.029999997466802597</scale>
					</mesh>
				</geometry>
			</collision>
			<visual name="VIS_Obj_4_Can">
				<pose>-6.83516263961792e-05 -0.003405354917049408 -0.0034073293209075928 4.6566137257286755e-07 3.1044091741705415e-08 -4.6566135836201283e-08</pose>
				<geometry>
					<mesh>
						<uri>model://google_grasp/meshes/visual/VIS_Obj_4_Can.dae</uri>
						<scale>0.029999999329447746 0.029999999329447746 0.029999997466802597</scale>
					</mesh>
				</geometry>
			</visual>
		</link>
		<link name="Obj_5">
			<self_collide>true</self_collide>
			<pose>0.07000000029802322 -0.7200000047683716 1.0 1.0629055500030518 -0.45727628469467163 0.7452555894851685</pose>
			<inertial>
				<mass>36.96764373779297</mass>
				<pose>0 0 0 0 0 0</pose>
				<inertia>
					<ixx>0.047036720275878906</ixx>
					<ixy>0.0</ixy>
					<ixz>0.0</ixz>
					<iyy>0.09572296905517578</iyy>
					<iyz>0.0</iyz>
					<izz>0.09578512573242188</izz>
				</inertia>
			</inertial>
			<collision name="COL_Obj_5_Football_Coll">
				<pose>0.00024674832820892334 -0.002815432846546173 -0.00025904737412929535 3.8029008919693297e-07 1.5522044805038604e-07 -4.268562037168522e-08</pose>
				<geometry>
					<mesh>
						<uri>model://google_grasp/meshes/collisions/COL_Obj_5_Football_Coll.dae</uri>
						<scale>0.029999999329447746 0.029999999329447746 0.029999999329447746</scale>
					</mesh>
				</geometry>
			</collision>
			<visual name="VIS_Obj_5_Football">
				<pose>0.00024674832820892334 -0.002815432846546173 -0.00025904737412929535 3.8029008919693297e-07 1.5522044805038604e-07 -4.268562037168522e-08</pose>
				<geometry>
					<mesh>
						<uri>model://football/meshes/visual/VIS_Obj_5_Football.dae</uri>
						<scale>0.029999999329447746 0.029999999329447746 0.029999999329447746</scale>
					</mesh>
				</geometry>
			</visual>
		</link>
		<link name="Obj_6">
			<self_collide>true</self_collide>
			<pose>0.30000001192092896 -0.7900000214576721 1.0 2.3212878704071045 -0.692895770072937 -0.16231562197208405</pose>
			<inertial>
				<mass>206.3406524658203</mass>
				<pose>0 0 0 0 0 0</pose>
				<inertia>
					<ixx>0.07458875122070312</ixx>
					<ixy>0.0</ixy>
					<ixz>0.0</ixz>
					<iyy>0.2093234375</iyy>
					<iyz>0.0</iyz>
					<izz>0.19273070068359375</izz>
				</inertia>
			</inertial>
			<collision name="COL_Obj_6_Lightbulb_Coll">
				<pose>0.06560074537992477 0.031300514936447144 0.053160324692726135 -0.008726583793759346 -3.0073960033405456e-07 -2.0372681319713593e-07</pose>
				<geometry>
					<mesh>
						<uri>model://google_grasp/meshes/collisions/COL_Obj_6_Lightbulb_Coll.dae</uri>
						<scale>0.012000000104308128 0.011999999172985554 0.012000000104308128</scale>
					</mesh>
				</geometry>
			</collision>
			<visual name="VIS_Obj_6_Lightbulb">
				<pose>0.06560074537992477 0.031300514936447144 0.053160324692726135 -0.008726583793759346 -3.0073960033405456e-07 -2.0372681319713593e-07</pose>
				<geometry>
					<mesh>
						<uri>model://google_grasp/meshes/visual/VIS_Obj_6_Lightbulb.dae</uri>
						<scale>0.012000000104308128 0.011999999172985554 0.012000000104308128</scale>
					</mesh>
				</geometry>
			</visual>
		</link>
		<link name="Obj_7">
			<self_collide>true</self_collide>
			<pose>-0.027499999850988388 -0.9700000286102295 1.00000143051147 -0.5253441333770752 -0.2059488594532013 -0.23911009728908542</pose>
			<inertial>
				<mass>602.91064453125</mass>
				<pose>0 0 0 0 0 0</pose>
				<inertia>
					<ixx>0.25</ixx>
					<ixy>0.0</ixy>
					<ixz>0.0</ixz>
					<iyy>0.1</iyy>
					<iyz>0.0</iyz>
					<izz>0.25</izz>
				</inertia>
			</inertial>
			<collision name="COL_Obj_7_Pin_Coll">
				<pose>-0.0018854988738894463 0.11175277829170227 -0.00020171012147329748 9.943810397317066e-08 5.335703434639072e-08 -1.9402557782655094e-08</pose>
				<geometry>
					<mesh>
						<uri>model://google_grasp/meshes/collisions/COL_Obj_7_Pin_Coll.dae</uri>
						<scale>0.011999999172985554 0.012000000104308128 0.012000000104308128</scale>
					</mesh>
				</geometry>
			</collision>
			<visual name="VIS_Obj_7_Pin">
				<pose>-0.0018854988738894463 0.11175277829170227 -0.00020171012147329748 9.943810397317066e-08 5.335703434639072e-08 -1.9402557782655094e-08</pose>
				<geometry>
					<mesh>
						<uri>model://google_grasp/meshes/visual/VIS_Obj_7_Pin.dae</uri>
						<scale>0.011999999172985554 0.012000000104308128 0.012000000104308128</scale>
					</mesh>
				</geometry>
			</visual>
		</link>



<!-- manipulation arm_0-->
		<link name="arm_0_link_link_base_z_rot">
			<pose>0.0 -0.4 1.0 0.0 -0.0 1.62316</pose>
			<inertial>
				<mass>0.29364</mass>
				<pose>0.0 0.0 0.0 0.0 -0.0 -0.0</pose>
				<inertia>
					<ixx>0.01</ixx>
					<ixy>0.0</ixy>
					<ixz>0.0</ixz>
					<iyy>0.01</iyy>
					<iyz>0.0</iyz>
					<izz>0.01</izz>
				</inertia>
			</inertial>
		</link>
<!-- arm_1 -->
		<link name="hollie_000">
			<pose>0 -0.4 1.11 0.0 -0.0 1.62316</pose>
			<inertial>
				<mass>0.29364</mass>
				<pose>0.0 0.0 0.0 0.0 -0.0 0.0</pose>
				<inertia>
					<ixx>0.01</ixx>
					<ixy>0.0</ixy>
					<ixz>0.0</ixz>
					<iyy>0.01</iyy>
					<iyz>0.0</iyz>
					<izz>0.01</izz>
				</inertia>
			</inertial>
			<collision name="VIS_hollhollie_000_Coll">
				<pose>3.52010e-08 1.03013e-07 1.54972e-06 -2.10125e-07 1.15808e-08 1.15484e-07</pose>
				<geometry>
					<mesh>
						<uri>model://google_grasp/meshes/visual/VIS_hollhollie_000_Coll.dae</uri>
						<scale>1.0 1.0 1.0</scale>
					</mesh>
				</geometry>
			</collision>
			<visual name="VIS_hollhollie_000">
				<pose>3.527899039568183e-08 1.0450104781511982e-07 1.5497207641601562e-06 -2.1012502315898018e-07 1.1580821634993299e-08 1.1548399925231934e-07</pose>
				<geometry>
					<mesh>
						<uri>model://google_grasp/meshes/visual/VIS_hollhollie_000.dae</uri>
						<scale>1.0 1.0 1.0</scale>
					</mesh>
				</geometry>
			</visual>
		</link>
<!-- arm_2 -->
		<link name="hollie_001_base_x_rot">
			<pose>0 -0.4 1.11 1.5708 0.0 1.62316</pose>
			<inertial>
				<mass>1.68311</mass>
				<pose>0.0 0.0 0.0 0.0 0.0 0.0</pose>
				<inertia>
					<ixx>0.03</ixx>
					<ixy>0.0</ixy>
					<ixz>0.0</ixz>
					<iyy>0.03</iyy>
					<iyz>0.0</iyz>
					<izz>0.03</izz>
				</inertia>
			</inertial>
			<collision name="VIS_hollhollie_001_base_x_rot_Coll">
				<pose>1.237239644069632e-07 1.4319995216283132e-06 2.0726911853508057e-10 -7.549789415861596e-08 4.842877388000488e-08 5.42986633433884e-08</pose>
				<geometry>
					<mesh>
						<uri>model://google_grasp/meshes/visual/VIS_hollhollie_001_base_x_rot_Coll.dae</uri>
						<scale>1.0 1.0 1.0</scale>
					</mesh>
				</geometry>
			</collision>
			<visual name="VIS_hollhollie_001_base_x_rot">
				<pose>9.382646481981283e-08 1.4319995216283132e-06 1.6081827536318372e-10 -7.549789415861596e-08 4.842877388000488e-08 5.42986633433884e-08</pose>
				<geometry>
					<mesh>
						<uri>model://google_grasp/meshes/visual/VIS_hollhollie_001_base_x_rot.dae</uri>
						<scale>1.0 1.0 1.0</scale>
					</mesh>
				</geometry>
			</visual>
		</link>
<!-- arm_3-->
		<link name="hollie_002_upper_x_rot">
			<pose>2.226621420892171e-06 -0.3999998892682126 1.4599999934433918 1.5707963705062908 -8.742278039484667e-08 -1.5184365510940514</pose>
			<inertial>
				<mass>2.1</mass>
				<pose>0.0 0.0 0.0 0.0 0.0 0.0</pose>
				<inertia>
					<ixx>0.03</ixx>
					<ixy>0.0</ixy>
					<ixz>0.0</ixz>
					<iyy>0.03</iyy>
					<iyz>0.0</iyz>
					<izz>0.03</izz>
				</inertia>
			</inertial>
			<collision name="VIS_hollhollie_002_upper_x_rot_Coll">
				<pose>-2.3484392386308173e-07 1.0386088433733676e-06 6.178673572776461e-09 1.1914856656858319e-07 5.252659320831299e-07 -2.3818108374484837e-08</pose>
				<geometry>
					<mesh>
						<uri>model://google_grasp/meshes/visual/VIS_hollhollie_002_upper_x_rot_Coll.dae</uri>
						<scale>1.0 1.0 1.0</scale>
					</mesh>
				</geometry>
			</collision>
			<visual name="VIS_hollhollie_002_upper_x_rot">
				<pose>-2.348423038256442e-07 1.0386088433733676e-06 6.147750752916181e-09 1.1914856656858319e-07 5.252659320831299e-07 -2.3818108374484837e-08</pose>
				<geometry>
					<mesh>
						<uri>model://google_grasp/meshes/visual/VIS_hollhollie_002_upper_x_rot.dae</uri>
						<scale>1.0 1.0 1.0</scale>
					</mesh>
				</geometry>
			</visual>
		</link>
<!--arm_4-->
		<link name="hollie_003">
			<pose>2.226621420892171e-06 -0.3999998892682126 1.4599999934433916 -4.2188485748648916e-15 2.384185794926842e-07 1.6231561024957353</pose>
			<inertial>
				<mass>1.68311</mass>
				<pose>0.0 0.0 0.0 0.0 0.0 0.0</pose>
				<inertia>
					<ixx>0.1</ixx>
					<ixy>0.1</ixy>
					<ixz>0.1</ixz>
					<iyy>0.1</iyy>
					<iyz>0.1</iyz>
					<izz>0.1</izz>
				</inertia>
			</inertial>
			<collision name="VIS_hollhollie_003_Coll">
				<pose>2.7709091909855488e-08 -1.3419257527402806e-07 5.3661583621078535e-08 2.55391114478698e-07 1.2251870629143014e-08 -6.332995639013461e-08</pose>
				<geometry>
					<mesh>
						<uri>model://google_grasp/meshes/visual/VIS_hollhollie_003_Coll.dae</uri>
						<scale>1.0 1.0 1.0</scale>
					</mesh>
				</geometry>
			</collision>
			<visual name="VIS_hollhollie_003">
				<pose>4.941942677305633e-08 -2.9045969540675287e-07 5.3661583621078535e-08 2.5077753207369824e-07 4.84698337022138e-10 -6.332995639013461e-08</pose>
				<geometry>
					<mesh>
						<uri>model://google_grasp/meshes/visual/VIS_hollhollie_003.dae</uri>
						<scale>1.0 1.0 1.0</scale>
					</mesh>
				</geometry>
			</visual>
		</link>
<!--arm_5-->
		<link name="hollie_004_wrist_x_rot">
			<pose>-0.005237775420036871 -0.40026984862109644 1.7650000005948487 1.5707963705063268 -2.384185794926808e-07 -1.518436702089857</pose>
			<inertial>
				<mass>0.807</mass>
				<pose>0.0 0.0 0.0 0.0 0.0 0.0</pose>
				<inertia>
					<ixx>0.03</ixx>
					<ixy>0.0</ixy>
					<ixz>0.0</ixz>
					<iyy>0.03</iyy>
					<iyz>0.0</iyz>
					<izz>0.03</izz>
				</inertia>
			</inertial>
			<collision name="VIS_hollhollie_004_wrist_x_rot_Coll">
				<pose>-2.576303472778818e-07 6.274480597312504e-07 -5.579038031555683e-08 1.9072874692938058e-06 -2.2016463390173158e-06 3.1112062259808226e-08</pose>
				<geometry>
					<mesh>
						<uri>model://google_grasp/meshes/visual/VIS_hollhollie_004_wrist_x_rot_Coll.dae</uri>
						<scale>1.0 1.0 1.0</scale>
					</mesh>
				</geometry>
			</collision>
			<visual name="VIS_hollhollie_004_wrist_x_rot">
				<pose>-2.2771160956835956e-07 6.274480597312504e-07 -5.625604160286457e-08 2.0264969862182625e-06 -2.2016463390173158e-06 -1.1550821454875404e-07</pose>
				<geometry>
					<mesh>
						<uri>model://google_grasp/meshes/visual/VIS_hollhollie_004_wrist_x_rot.dae</uri>
						<scale>1.0 1.0 1.0</scale>
					</mesh>
				</geometry>
			</visual>
		</link>
<!--arm_6-->
		<link name="hollie_005">
			<pose>-0.005237775420036867 -0.40026984862109644 1.7650000005948487 4.019007348745999e-14 -2.384185794926808e-07 -1.518436702089857</pose>
			<inertial>
				<mass>0.819</mass>
				<pose>0.0 0.0 0.0 0.0 0.0 0.0</pose>
				<inertia>
					<ixx>0.01</ixx>
					<ixy>0.0</ixy>
					<ixz>0.0</ixz>
					<iyy>0.01</iyy>
					<iyz>0.0</iyz>
					<izz>0.01</izz>
				</inertia>
			</inertial>
			<collision name="VIS_hollhollie_005_Coll">
				<pose>-7.496467446799215e-08 4.749598190301185e-07 1.7147423250207794e-06 1.4999766762002764e-08 8.693253761293818e-08 4.172325134277344e-07</pose>
				<geometry>
					<mesh>
						<uri>model://google_grasp/meshes/visual/VIS_hollhollie_005_Coll.dae</uri>
						<scale>1.0 1.0 1.0</scale>
					</mesh>
				</geometry>
			</collision>
			<visual name="VIS_hollhollie_005">
				<pose>-7.650720590390847e-08 4.460888476387481e-07 1.5955330354699981e-06 2.4900401740524103e-08 8.122043482217123e-08 4.172325134277344e-07</pose>
				<geometry>
					<mesh>
						<uri>model://google_grasp/meshes/visual/VIS_hollhollie_005.dae</uri>
						<scale>1.0 1.0 1.0</scale>
					</mesh>
				</geometry>
			</visual>
		</link>
<!--gripper -->
		<link name="base">
			<pose>-0.005237775420036867 -0.40026984862109644 1.84000005948487 1.5707963705062866 -0.0 0.0</pose>
			<inertial>
				<mass>1.0</mass>
				<pose>0 0 0 0 0 0</pose>
				<inertia>
					<ixx>1.0</ixx>
					<ixy>0.0</ixy>
					<ixz>0.0</ixz>
					<iyy>1.0</iyy>
					<iyz>0.0</iyz>
					<izz>1.0</izz>
				</inertia>
			</inertial>
			<collision name="COL__SCHUNK-1009735_G0_COL">
				<pose>4.1560057348688105e-09 -1.1114451746924874e-10 1.489013379246894e-10 -1.5707963705062866 -2.277714316137395e-22 0.0</pose>
				<geometry>
					<mesh>
						<uri>model://google_grasp/meshes/collisions/COL__SCHUNK-1009735_G0_COL.dae</uri>
						<scale>0.0010000000623986132 0.0010000000623986132 0.0012000000748783358</scale>
					</mesh>
				</geometry>
			</collision>
			<visual name="VIS__SCHUNK-1009530_R14">
				<pose>4.1560057348688105e-09 -1.1114451746924874e-10 1.489013379246894e-10 -1.5707963705062866 -2.277714316137395e-22 0.0</pose>
				<geometry>
					<mesh>
						<uri>model://google_grasp/meshes/visual/VIS__SCHUNK-1009530_R14.dae</uri>
						<scale>0.0010000000623986132 0.0010000000623986132 0.0010000000623986132</scale>
					</mesh>
				</geometry>
			</visual>
			<visual name="VIS__SCHUNK-1009540_R10">
				<pose>4.1560057348688105e-09 -1.1114451746924874e-10 1.489013379246894e-10 -1.5707963705062866 -2.277714316137395e-22 0.0</pose>
				<geometry>
					<mesh>
						<uri>model://google_grasp/meshes/visual/VIS__SCHUNK-1009540_R10.dae</uri>
						<scale>0.0010000000623986132 0.0010000000623986132 0.0010000000623986132</scale>
					</mesh>
				</geometry>
			</visual>
			<visual name="VIS__SCHUNK-1009598_S12">
				<pose>4.1560057348688105e-09 -1.1114451746924874e-10 1.489013379246894e-10 -1.5707963705062866 -2.277714316137395e-22 0.0</pose>
				<geometry>
					<mesh>
						<uri>model://google_grasp/meshes/visual/VIS__SCHUNK-1009598_S12.dae</uri>
						<scale>0.0010000000623986132 0.0010000000623986132 0.0010000000623986132</scale>
					</mesh>
				</geometry>
			</visual>
			<visual name="VIS__SCHUNK-1009598_S13">
				<pose>4.1560057348688105e-09 -1.1114451746924874e-10 1.489013379246894e-10 -1.5707963705062866 -2.277714316137395e-22 0.0</pose>
				<geometry>
					<mesh>
						<uri>model://google_grasp/meshes/visual/VIS__SCHUNK-1009598_S13.dae</uri>
						<scale>0.0010000000623986132 0.0010000000623986132 0.0010000000623986132</scale>
					</mesh>
				</geometry>
			</visual>
			<visual name="VIS__SCHUNK-1009598_S16">
				<pose>4.1560057348688105e-09 -1.1114451746924874e-10 1.489013379246894e-10 -1.5707963705062866 -2.277714316137395e-22 0.0</pose>
				<geometry>
					<mesh>
						<uri>model://google_grasp/meshes/visual/VIS__SCHUNK-1009598_S16.dae</uri>
						<scale>0.0010000000623986132 0.0010000000623986132 0.0010000000623986132</scale>
					</mesh>
				</geometry>
			</visual>
			<visual name="VIS__SCHUNK-1009598_S17">
				<pose>4.1560057348688105e-09 -1.1114451746924874e-10 1.489013379246894e-10 -1.5707963705062866 -2.277714316137395e-22 0.0</pose>
				<geometry>
					<mesh>
						<uri>model://google_grasp/meshes/visual/VIS__SCHUNK-1009598_S17.dae</uri>
						<scale>0.0010000000623986132 0.0010000000623986132 0.0010000000623986132</scale>
					</mesh>
				</geometry>
			</visual>
			<visual name="VIS__SCHUNK-1009599_S11">
				<pose>4.1560057348688105e-09 -1.1114451746924874e-10 1.489013379246894e-10 -1.5707963705062866 -2.277714316137395e-22 0.0</pose>
				<geometry>
					<mesh>
						<uri>model://google_grasp/meshes/visual/VIS__SCHUNK-1009599_S11.dae</uri>
						<scale>0.0010000000623986132 0.0010000000623986132 0.0010000000623986132</scale>
					</mesh>
				</geometry>
			</visual>
			<visual name="VIS__SCHUNK-1009599_S15">
				<pose>4.1560057348688105e-09 -1.1114451746924874e-10 1.489013379246894e-10 -1.5707963705062866 -2.277714316137395e-22 0.0</pose>
				<geometry>
					<mesh>
						<uri>model://google_grasp/meshes/visual/VIS__SCHUNK-1009599_S15.dae</uri>
						<scale>0.0010000000623986132 0.0010000000623986132 0.0010000000623986132</scale>
					</mesh>
				</geometry>
			</visual>
			<visual name="VIS__SCHUNK-1009735_G0">
				<pose>4.1560057348688105e-09 -1.1114451746924874e-10 1.489013379246894e-10 -1.5707963705062866 -2.277714316137395e-22 0.0</pose>
				<geometry>
					<mesh>
						<uri>model://google_grasp/meshes/visual/VIS__SCHUNK-1009735_G0.dae</uri>
						<scale>0.0010000000623986132 0.0010000000623986132 0.0010000000623986132</scale>
					</mesh>
				</geometry>
			</visual>
			<visual name="VIS__SCHUNK-1010072_B8">
				<pose>4.1560057348688105e-09 -1.1114451746924874e-10 1.489013379246894e-10 -1.5707963705062866 -2.277714316137395e-22 0.0</pose>
				<geometry>
					<mesh>
						<uri>model://google_grasp/meshes/visual/VIS__SCHUNK-1010072_B8.dae</uri>
						<scale>0.0010000000623986132 0.0010000000623986132 0.0010000000623986132</scale>
					</mesh>
				</geometry>
			</visual>
			<visual name="VIS__SCHUNK-1010073_B6">
				<pose>4.1560057348688105e-09 -1.1114451746924874e-10 1.489013379246894e-10 -1.5707963705062866 -2.277714316137395e-22 0.0</pose>
				<geometry>
					<mesh>
						<uri>model://google_grasp/meshes/visual/VIS__SCHUNK-1010073_B6.dae</uri>
						<scale>0.0010000000623986132 0.0010000000623986132 0.0010000000623986132</scale>
					</mesh>
				</geometry>
			</visual>
			<visual name="VIS__SCHUNK-9957615_T2">
				<pose>4.1560057348688105e-09 -1.1114451746924874e-10 1.489013379246894e-10 -1.5707963705062866 -2.277714316137395e-22 0.0</pose>
				<geometry>
					<mesh>
						<uri>model://google_grasp/meshes/visual/VIS__SCHUNK-9957615_T2.dae</uri>
						<scale>0.0010000000623986132 0.0010000000623986132 0.0010000000623986132</scale>
					</mesh>
				</geometry>
			</visual>
		</link>
		<link name="wrist">
			<pose>-0.005 -0.4 1.96 1.5707963705062866 -0.0 0.0</pose>
			<inertial>
				<mass>0.3</mass>
				<pose>0 0 0 0 0 0</pose>
				<inertia>
					<ixx>1.0</ixx>
					<ixy>0.0</ixy>
					<ixz>0.0</ixz>
					<iyy>1.0</iyy>
					<iyz>0.0</iyz>
					<izz>1.0</izz>
				</inertia>
			</inertial>
			<visual name="VIS__SCHUNK-1009497_Z9">
				<pose>8.312032075477265e-09 -0.11499996356666031 2.2851623156749145e-10 -1.5707963705062866 -1.4425274595939708e-22 3.308722197776621e-22</pose>
				<geometry>
					<mesh>
						<uri>model://google_grasp/meshes/visual/VIS__SCHUNK-1009497_Z9.dae</uri>
						<scale>0.0010000000623986132 0.0010000000623986132 0.0010000000623986132</scale>
					</mesh>
				</geometry>
			</visual>
			<visual name="VIS__SCHUNK-1009525_G3">
				<pose>8.312032075477265e-09 -0.11499996356666031 2.2851623156749145e-10 -1.5707963705062866 -1.4425274595939708e-22 3.308722197776621e-22</pose>
				<geometry>
					<mesh>
						<uri>model://google_grasp/meshes/visual/VIS__SCHUNK-1009525_G3.dae</uri>
						<scale>0.0010000000623986132 0.0010000000623986132 0.0010000000623986132</scale>
					</mesh>
				</geometry>
			</visual>
			<visual name="VIS__SCHUNK-5521117_A4">
				<pose>8.312032075477265e-09 -0.11499996356666031 2.2851623156749145e-10 -1.5707963705062866 -1.4425274595939708e-22 3.308722197776621e-22</pose>
				<geometry>
					<mesh>
						<uri>model://google_grasp/meshes/visual/VIS__SCHUNK-5521117_A4.dae</uri>
						<scale>0.0010000000623986132 0.0010000000623986132 0.0010000000623986132</scale>
					</mesh>
				</geometry>
			</visual>


			<visual name="VIS__SCHUNK-9905503_T1">
				<pose>8.312032075477265e-09 -0.11499996356666031 2.2851623156749145e-10 -1.5707963705062866 -1.4425274595939708e-22 3.308722197776621e-22</pose>
				<geometry>
					<mesh>
						<uri>model://google_grasp/meshes/visual/VIS__SCHUNK-9905503_T1.dae</uri>
						<scale>0.0010000000623986132 0.0010000000623986132 0.0010000000623986132</scale>
					</mesh>
				</geometry>
			</visual>
		</link>
		<link name="finger1">
			<pose>0.028000000536441805 -0.4 1.979 1.5707963705062866 -0.0 0.0</pose>
			<inertial>
				<mass>0.1</mass>
				<pose>0 0 0 0 0 0</pose>
				<inertia>
					<ixx>1.0</ixx>
					<ixy>0.0</ixy>
					<ixz>0.0</ixz>
					<iyy>1.0</iyy>
					<iyz>0.0</iyz>
					<izz>1.0</izz>
				</inertia>
			</inertial>
			<collision name="COL_Finger1_COL.001">
				<pose>-0.027999964773654407 -0.13500004015862999 2.2851623156749145e-10 1.5099581673894136e-07 3.1415927410125732 -1.5099578831723193e-07</pose>
				<geometry>
					<mesh>
						<uri>model://google_grasp/meshes/collisions/COL_Finger1_COL.dae</uri>
						<scale>0.0010000000623986132 0.0010000000623986132 0.0010000000623986132</scale>
					</mesh>
				</geometry>
			</collision>
			<visual name="VIS_Finger1_VIS.001">
				<pose>-0.027999964773654407 -0.13500004015862999 2.2851623156749145e-10 1.5099581673894136e-07 3.1415927410125732 -1.5099578831723193e-07</pose>
				<geometry>
					<mesh>
						<uri>model://google_grasp/meshes/visual/VIS_Finger1_VIS.dae</uri>
						<scale>0.0010000000623986132 0.0010000000623986132 0.0010000000623986132</scale>
					</mesh>
				</geometry>
			</visual>
			<visual name="VIS__SCHUNK-5521119_F7">
				<pose>-0.025 -0.1338 2.2851623156749145e-10 -1.5707963705062866 -1.4425274595939708e-22 3.308722197776621e-22</pose>
				<geometry>
					<mesh>
						<uri>model://google_grasp/meshes/visual/VIS__SCHUNK-5521119_F7.dae</uri>
						<scale>0.0010000000623986132 0.0010000000623986132 0.0010000000623986132</scale>
					</mesh>
				</geometry>
			</visual>

		</link>
		<link name="finger2">
			<pose>-0.028000000536441805 -0.4 1.979 1.5707963705062866 -0.0 0.0</pose>
			<inertial>
				<mass>0.1</mass>
				<pose>0 0 0 0 0 0</pose>
				<inertia>
					<ixx>1.0</ixx>
					<ixy>0.0</ixy>
					<ixz>0.0</ixz>
					<iyy>1.0</iyy>
					<iyz>0.0</iyz>
					<izz>1.0</izz>
				</inertia>
			</inertial>
			<collision name="COL_Finger2_COL.001">
				<pose>0.02799998563528039 -0.13499984942376386 1.7515162914577036e-10 -4.614361057966518e-15 8.742279078433057e-08 -8.593264766432185e-08</pose>
				<geometry>
					<mesh>
						<uri>model://google_grasp/meshes/collisions/COL_Finger2_COL.dae</uri>
						<scale>0.0010000000623986132 0.0010000000623986132 0.0010000000623986132</scale>
					</mesh>
				</geometry>
			</collision>
			<visual name="VIS_Finger2_VIS.001">
				<pose>0.02799998563528039 -0.13499984942376386 1.7515162914577036e-10 -4.614361057966518e-15 8.742279078433057e-08 -8.593264766432185e-08</pose>
				<geometry>
					<mesh>
						<uri>model://google_grasp/meshes/visual/VIS_Finger2_VIS.dae</uri>
						<scale>0.0010000000623986132 0.0010000000623986132 0.0010000000623986132</scale>
					</mesh>
				</geometry>
			</visual>
			<visual name="VIS__SCHUNK-5521119_F5">
				<pose>0.025 -0.1338 2.2851623156749145e-10 -1.5707963705062866 -1.4425274595939708e-22 3.308722197776621e-22</pose>
				<geometry>
					<mesh>
						<uri>model://google_grasp/meshes/visual/VIS__SCHUNK-5521119_F5.dae</uri>
						<scale>0.0010000000623986132 0.0010000000623986132 0.0010000000623986132</scale>
					</mesh>
				</geometry>
			</visual>

		</link>

		<!-- attach gripper to robot-->
		<joint name="gripper_attach" type="prismatic">
			<parent>hollie_005</parent>
			<child>base</child>
			<axis>
				<xyz>0.0 1.0 0.0</xyz>
				<limit>
					<lower>0</lower>
					<upper>0</upper>
				</limit>
        			<use_parent_model_frame>1</use_parent_model_frame>
			</axis>

		</joint>


		<joint name="wrist_gripper" type="revolute">
			<parent>base</parent>
			<child>wrist</child>
			<axis>
				<xyz>0.0 1.0 0.0</xyz>
				<limit>
					<lower>-1.5707963267948966</lower>
					<upper>1.5707963267948966</upper>
				</limit>
        			
			</axis>
		</joint>
		<joint name="finger1_joint" type="prismatic">
			<parent>wrist</parent>
			<child>finger1</child>
			<axis>
				<xyz>1.0 0.0 0.0</xyz>
				<limit>
					<lower>-0.01</lower>
					<upper>0.01</upper>
				</limit>
        			
			</axis>
		</joint>
		<joint name="finger2_joint" type="prismatic">
			<parent>wrist</parent>
			<child>finger2</child>
			<axis>
				<xyz>1.0 0.0 0.0</xyz>
				<limit>
					<lower>-0.01</lower>
					<upper>0.01</upper>
				</limit>
        			
			</axis>
		</joint>


<!-- end gripper -->
		
		<joint name="arm_0_joint_base_z_rot" type="prismatic">
			<parent>base_link</parent>
			<child>arm_0_link_link_base_z_rot</child>
			<axis>
				<xyz>-0.0523359 0.99863 0</xyz>
				<limit>
					<lower>0</lower>
					<upper>0</upper>
  				        <effort>1000</effort>
       					<velocity>1</velocity>
				</limit>			
				<dynamics>
          				<damping>1</damping>
          				<friction>0</friction>
          				<spring_reference>0</spring_reference>
          				<spring_stiffness>0</spring_stiffness>
        			</dynamics>
        			<use_parent_model_frame>1</use_parent_model_frame>
			</axis>

		</joint>
		<joint name="hollie_000_joint" type="revolute">
			<parent>arm_0_link_link_base_z_rot</parent>
			<child>hollie_000</child>
			<axis>
				<xyz>0.0 0.0 1.0</xyz>
				<limit>
					<lower></lower>
					<upper></upper>
  				        <effort>1000</effort>
       					<velocity>10</velocity>
				</limit>
				<dynamics>
          				<damping>1</damping>
          				<friction>0</friction>
          				<spring_reference>0</spring_reference>
          				<spring_stiffness>0</spring_stiffness>
        			</dynamics>
        			<use_parent_model_frame>1</use_parent_model_frame>
			</axis>
		</joint>
		<joint name="hollie_001_base_x_rot_joint" type="revolute">
			<parent>hollie_000</parent>
			<child>hollie_001_base_x_rot</child>
			<axis>
				<xyz>0.99863 0.0523359 -4.37114e-08</xyz>
				<limit>
					<lower>-1.5707963</lower>
					<upper>1.5707963</upper>
  				        <effort>1000</effort>
       					<velocity>1</velocity>
				</limit>
				<dynamics>
          				<damping>1</damping>
          				<friction>0</friction>
          				<spring_reference>0</spring_reference>
          				<spring_stiffness>0</spring_stiffness>
        			</dynamics>
        			<use_parent_model_frame>1</use_parent_model_frame>
			</axis>
		</joint>
		<joint name="hollie_002_upper_x_rot_joint" type="revolute">
			<parent>hollie_001_base_x_rot</parent>
			<child>hollie_002_upper_x_rot</child>
			<axis>
				<xyz>-0.99863 -0.0523361 4.37114e-08</xyz>
				<limit>
					<lower>-2.748893571891069</lower>
					<upper>2.748893571891069</upper>
  				        <effort>1000</effort>
       					<velocity>10</velocity>
				</limit>
				<dynamics>
          				<damping>1</damping>
          				<friction>0</friction>
          				<spring_reference>0</spring_reference>
          				<spring_stiffness>0</spring_stiffness>
        			</dynamics>
        			<use_parent_model_frame>1</use_parent_model_frame>
			</axis>
		</joint>
		<joint name="hollie_003_joint" type="revolute">
			<parent>hollie_002_upper_x_rot</parent>
			<child>hollie_003</child>
			<axis>
				<xyz>9.52055e-08 -1.46214e-07 1</xyz>
				<limit>
					<lower></lower>
					<upper></upper>
  				        <effort>1000</effort>
       					<velocity>10</velocity>
				</limit>
				<dynamics>
          				<damping>1</damping>
          				<friction>0</friction>
          				<spring_reference>0</spring_reference>
          				<spring_stiffness>0</spring_stiffness>
        			</dynamics>
        			<use_parent_model_frame>1</use_parent_model_frame>
			</axis>
		</joint>
		<joint name="hollie_004_wrist_x_rot_joint" type="revolute">
			<parent>hollie_003</parent>
			<child>hollie_004_wrist_x_rot</child>
			<axis>
				<xyz>-0.99863 -0.0523362 4.37114e-08</xyz>
				<limit>
					<lower>-2.6179938779914944</lower>
					<upper>2.6179938779914944</upper>
  				        <effort>1000</effort>
       					<velocity>1</velocity>
				</limit>
				<dynamics>
          				<damping>1</damping>
          				<friction>0</friction>
          				<spring_reference>0</spring_reference>
          				<spring_stiffness>0</spring_stiffness>
        			</dynamics>
        			<use_parent_model_frame>1</use_parent_model_frame>
			</axis>
		</joint>
		<joint name="hollie_005_joint" type="revolute">
			<parent>hollie_004_wrist_x_rot</parent>
			<child>hollie_005</child>
			<axis>
				<xyz>9.52055e-08 -1.46214e-07 1</xyz>
				<limit>
					<lower></lower>
					<upper></upper>
  				        <effort>1000</effort>
       					<velocity>1</velocity>
				</limit>
				<dynamics>
          				<damping>1</damping>
          				<friction>0</friction>
          				<spring_reference>0</spring_reference>
          				<spring_stiffness>0</spring_stiffness>
        			</dynamics>
        			<use_parent_model_frame>1</use_parent_model_frame>
			</axis>
		</joint>
		<joint name="hollie_006_wrist_lat_rot_joint" type="prismatic">
			<parent>hollie_005</parent>
			<child>hollie_006_wrist_lat_rot</child>
			<axis>
				<xyz>0.0523362 -0.99863 -1.50996e-07</xyz>
				<limit>
					<lower>0</lower>
					<upper>0</upper>
  				        <effort>1000</effort>
       					<velocity>1</velocity>
				</limit>
				<dynamics>
          				<damping>1</damping>
          				<friction>0</friction>
          				<spring_reference>0</spring_reference>
          				<spring_stiffness>0</spring_stiffness>
        			</dynamics>
        			<use_parent_model_frame>1</use_parent_model_frame>
			</axis>
		</joint>
		<joint name="hollie_007_wrist_lat_rot_joint" type="prismatic">
			<parent>hollie_006_wrist_lat_rot</parent>
			<child>hollie_007_wrist_lat_rot</child>
			<axis>
				<xyz>0.0523362 -0.99863 -1.50996e-07</xyz>
				<limit>
					<lower>0</lower>
					<upper>0</upper>
  				        <effort>1000</effort>
       					<velocity>1</velocity>
				</limit>
				<dynamics>
          				<damping>1</damping>
          				<friction>0</friction>
          				<spring_reference>0</spring_reference>
          				<spring_stiffness>0</spring_stiffness>
        			</dynamics>
        			<use_parent_model_frame>1</use_parent_model_frame>
			</axis>
		</joint>
		

    
<!--    PID controller	-->
    <static>0</static>
    

    <plugin name="grasp_schunk" filename="libgeneric_controller_plugin.so" >

 <!--   <controller joint_name="arm_0_joint_base_z_rot">
        <type>position</type>
	<pid>500.0 10.0 50.0</pid>
    </controller>
-->

    <controller joint_name="hollie_000_joint">
        <type>position</type>
	<pid>500.0 10.0 50.0</pid>
    </controller>
  
    <controller joint_name="hollie_001_base_x_rot_joint">
        <type>position</type>
	<pid>500.0 10.0 50.0</pid>
    </controller>

    <controller joint_name="hollie_002_upper_x_rot_joint">
        <type>position</type>
	<pid>500.0 10.0 50.0</pid>
    </controller>

    <controller joint_name="hollie_003_joint">
        <type>position</type>
	<pid>500.0 10.0 50.0</pid>
    </controller>

     <controller joint_name="hollie_004_wrist_x_rot_joint">
        <type>position</type>
	<pid>500.0 10.0 50.0</pid>
    </controller>

    <controller joint_name="hollie_005_joint">
        <type>position</type>
	<pid>500.0 10.0 50.0</pid>
    </controller>

    <controller joint_name="hand_f1_joint">
        <type>position</type>
	<pid>100.0 0.1 0.1</pid>
    </controller>

    <controller joint_name="hand_f2_joint">
        <type>position</type>
	<pid>100.0 0.1 0.1</pid>
    </controller>

    <controller joint_name="hand_f3_joint">
        <type>position</type>
	<pid>100.0 0.1 0.1</pid>
    </controller>

    <controller joint_name="hand_f5_link_joint">
        <type>position</type>
	<pid>100.0 0.1 0.1</pid>
    </controller>

    <controller joint_name="hand_f6_link_joint">
        <type>position</type>
	<pid>100.0 0.1 0.1</pid>
    </controller>

    <controller joint_name="hand_f8_joint">
        <type>position</type>
	<pid>100.0 0.1 0.1</pid>
    </controller>
  
    <controller joint_name="hollie_006_wrist_lat_rot_joint">
        <type>position</type>
	<pid>100.0 0.1 0.1</pid>
    </controller>

    <controller joint_name="hollie_007_wrist_lat_rot_joint">
        <type>position</type>
	<pid>100.0 0.1 0.1</pid>
    </controller>

 
<!-- gripper controller -->
    <controller joint_name="wrist_gripper">
        <type>position</type>
	<pid>100.0 0.1 0.1</pid>
    </controller>
    <controller joint_name="finger1">
        <type>position</type>
	<pid>100.0 0.1 0.1</pid>
    </controller>
    <controller joint_name="finger2">
        <type>position</type>
	<pid>100.0 0.1 0.1</pid>
    </controller>

    </plugin>
 
<!-- grasp plugin -->
   <plugin name="gazebo_grasp_fix" filename="libgazebo_grasp_fix.so">
        <arm>
           <arm_name>robot</arm_name>
           <palm_link>finger1</palm_link>
           <gripper_link>finger2</gripper_link>
        </arm>
       <forces_angle_tolerance>100</forces_angle_tolerance>
       <update_rate>4</update_rate>
       <grip_count_threshold>4</grip_count_threshold>
       <max_grip_count>8</max_grip_count>
       <release_tolerance>0.005</release_tolerance>
       <disable_collisions_on_attach>false</disable_collisions_on_attach>
       <contact_topic>__default_topic__</contact_topic>
    </plugin>
   -->

</model>
</sdf>

